[2025-03-02T22:49:57.021+0000] {local_task_job_runner.py:123} INFO - ::group::Pre task execution logs
[2025-03-02T22:49:57.061+0000] {taskinstance.py:2614} INFO - Dependencies all met for dep_context=non-requeueable deps ti=<TaskInstance: scraping_pipeline_gcs.dvc_push manual__2025-03-02T22:49:27.430309+00:00 [queued]>
[2025-03-02T22:49:57.079+0000] {taskinstance.py:2614} INFO - Dependencies all met for dep_context=requeueable deps ti=<TaskInstance: scraping_pipeline_gcs.dvc_push manual__2025-03-02T22:49:27.430309+00:00 [queued]>
[2025-03-02T22:49:57.079+0000] {taskinstance.py:2867} INFO - Starting attempt 1 of 3
[2025-03-02T22:49:57.088+0000] {taskinstance.py:2890} INFO - Executing <Task(PythonOperator): dvc_push> on 2025-03-02 22:49:27.430309+00:00
[2025-03-02T22:49:57.102+0000] {warnings.py:112} WARNING - /home/***/.local/lib/python3.12/site-packages/***/task/task_runner/standard_task_runner.py:70: DeprecationWarning: This process (pid=1350) is multi-threaded, use of fork() may lead to deadlocks in the child.
  pid = os.fork()

[2025-03-02T22:49:57.105+0000] {standard_task_runner.py:104} INFO - Running: ['***', 'tasks', 'run', 'scraping_pipeline_gcs', 'dvc_push', 'manual__2025-03-02T22:49:27.430309+00:00', '--job-id', '177', '--raw', '--subdir', 'DAGS_FOLDER/dag.py', '--cfg-path', '/tmp/tmpw4q4enp0']
[2025-03-02T22:49:57.107+0000] {standard_task_runner.py:105} INFO - Job 177: Subtask dvc_push
[2025-03-02T22:49:57.107+0000] {standard_task_runner.py:72} INFO - Started process 1352 to run task
[2025-03-02T22:49:57.131+0000] {task_command.py:467} INFO - Running <TaskInstance: scraping_pipeline_gcs.dvc_push manual__2025-03-02T22:49:27.430309+00:00 [running]> on host 5e87a20f9330
[2025-03-02T22:49:57.169+0000] {taskinstance.py:3134} INFO - Exporting env vars: AIRFLOW_CTX_DAG_OWNER='***' AIRFLOW_CTX_DAG_ID='scraping_pipeline_gcs' AIRFLOW_CTX_TASK_ID='dvc_push' AIRFLOW_CTX_EXECUTION_DATE='2025-03-02T22:49:27.430309+00:00' AIRFLOW_CTX_TRY_NUMBER='1' AIRFLOW_CTX_DAG_RUN_ID='manual__2025-03-02T22:49:27.430309+00:00'
[2025-03-02T22:49:57.170+0000] {logging_mixin.py:190} INFO - Task instance is in running state
[2025-03-02T22:49:57.170+0000] {logging_mixin.py:190} INFO -  Previous state of the Task instance: queued
[2025-03-02T22:49:57.170+0000] {logging_mixin.py:190} INFO - Current task name:dvc_push state:running start_date:2025-03-02 22:49:57.061807+00:00
[2025-03-02T22:49:57.170+0000] {logging_mixin.py:190} INFO - Dag name:scraping_pipeline_gcs and current dag run status:running
[2025-03-02T22:49:57.170+0000] {taskinstance.py:732} INFO - ::endgroup::
[2025-03-02T22:49:57.175+0000] {connection.py:277} WARNING - Connection schemes (type: google_cloud_platform) shall not contain '_' according to RFC3986.
[2025-03-02T22:49:57.181+0000] {base.py:84} INFO - Retrieving connection 'gcp_service_account'
[2025-03-02T22:49:57.181+0000] {logging_mixin.py:190} INFO - {'keyfile_dict': '{   "type": "service_account",   "project_id": "dev-testing-449422",   "private_key_id": "0d2b1bfdf1c62dd3c5788e426d76399161c12862",   "private_key": "-----BEGIN PRIVATE KEY-----\\nMIIEvAIBADANBgkqhkiG9w0BAQEFAASCBKYwggSiAgEAAoIBAQDBGJZ67wIA0t8g\\nkufEY2n9ev35QbktxBTjFLtoymR1zWlLveadWdmyAYYzfhlkvmgS8YCMzSoozmzY\\nu6uFBS92O+csYoQ/djQm7TTI4EPEgAsEkSgdTVIROVPbwAvbiM8bPqmK54usvHT+\\naLec6cQQ4y+iIZzAG2tMGiT695DtBUS+ZCVcMy60F1Wo3SzCL51wY7U4opeCnOSr\\nuKDDJNJCfxSXdOz4F1n6UUcbRgwXLlZGx2V/TOIWME0Aw8v3ErBXNH82mc0G1UDG\\nr4uqfyw0VTYESjGhrwWUsb397JWO4IByTVp3wvaO07E1umN6sbljuDG15Tnhb2vD\\nt5XVpM9RAgMBAAECggEAENKxU5MMr+EvVuFtp1bI9nBXfbab6VCWyET3YfUWJQxJ\\nIvPvymA4XvGSjVxsXnJXU2Uuf7XlOSpo4cYR9rQhszGbXarUnknQV97dNS4SwWUt\\ncI+r+MeSgZUmyPO1pMIJ1zQRpdwv91Pw9nRNoPJd5mHAteWrSDJrWfVCKQpWGkwv\\nMANq9cZvpp0GjQEWR2lTuclixuh9vbk3FDmmhxv9pZVaKMdMJqd3RpyjmzKUkdUE\\nkHmSbyekiUxwkTJoPdgzxtzRTW52nxA7z6k9RjYYHe90IFTZcwm8pJDR0Ly4i8ia\\nyc09RQa4NlDcMveBimeZcUIPi1t/Rp+E5A3miYztZQKBgQDndjcG4SIw1/Z0M0OW\\nhECBbyNKB2xSZNq6I6sL3l4Y1GuyX+R91OBkMNdWUT+nV46TCx7PZjB0EzYGo+4S\\nwL+/o/PjWYOc4tpziNnOrSrGtcQskoH0FTfIMMuqHSwBCewY5S/WTTIzpZ9y6HTX\\nhooP+2rOxsKYQa38tFSf8zvHdQKBgQDVkSQ1jRssMfsN9RVxlsKAx2uAu9fC1jmp\\nbhgbTJHfxbT4sM0zYpWlEXmSdmA1rNKk+wWc78ILOBND+BFp4wLB7wwwSrheAZMr\\nfZx8cJMBf531PpS+0JLq7IxPmK1sM2RbEZeOOE7dYoDmfOZ49WpONP/AVJAOzfTn\\nio8s7BuI7QKBgHO42N4ppSyCbQe/saUJTi7oX95dQ70WC31Q4+21KZqEaavu4ZA/\\n5EhzWtYfHRIPZosB3k+XKdZ+3F4Ji7f4gmXQFNmwIWtIyCtHWo5IacCblA8s2Kgu\\nC4udSdYta5jBWzc/LuGYCudjgQq0SeaPr2s6KjZjjVsOS2yyxDSMKXEZAoGAR4M/\\nZbMnSyg9UdIkaRG7dZXROJ0txW8ohcR4zANawVyZmcDSJYe4Zjqww8thsfd53Ya0\\nvXVHO6x+Pv89DYDXdosOQMl0bP4IAsMf+EdV4mWSRgG7mx2KZKHq5ehRAe8/hoMg\\nhZ3zQoxubz+ZiR1ciG2UyhlG1749aJ7sDHXPTo0CgYAVZJoqSI/x5SYTDEQDpwcc\\nfpGjdmImWjS5ar8WHbR4NxGa3b3byxMtRfb6N+Q9jEIEq2VrVQQpYuUnoTa4lW3L\\nL8S266B++zWrPCK9zR4/HUg3OwnRP9gv4mn7a8xJOX7qarAlmhbYuMjEwIxi2dyP\\nZM3vt8MQr1dm4qZDkrVwUQ==\\n-----END PRIVATE KEY-----\\n",   "client_email": "128371203639-compute@developer.gserviceaccount.com",   "client_id": "105621837324697304677",   "auth_uri": "https://accounts.google.com/o/oauth2/auth",   "token_uri": "https://oauth2.googleapis.com/token",   "auth_provider_x509_cert_url": "https://www.googleapis.com/oauth2/v1/certs",   "client_x509_cert_url": "https://www.googleapis.com/robot/v1/metadata/x509/128371203639-compute%40developer.gserviceaccount.com",   "universe_domain": "googleapis.com" }', 'num_retries': 5, 'is_anonymous': False}
[2025-03-02T22:49:58.089+0000] {taskinstance.py:3313} ERROR - Task failed with exception
Traceback (most recent call last):
  File "/opt/airflow/dags/dag.py", line 56, in dvc_push_to_gcs
    subprocess.run(["dvc", "add", SCRAPED_TEXT_DIR], check=True)
  File "/usr/local/lib/python3.12/subprocess.py", line 573, in run
    raise CalledProcessError(retcode, process.args,
subprocess.CalledProcessError: Command '['dvc', 'add', '/opt/airflow/dags/src/scraped_texts']' returned non-zero exit status 253.

During handling of the above exception, another exception occurred:

Traceback (most recent call last):
  File "/home/airflow/.local/lib/python3.12/site-packages/airflow/models/taskinstance.py", line 768, in _execute_task
    result = _execute_callable(context=context, **execute_callable_kwargs)
             ^^^^^^^^^^^^^^^^^^^^^^^^^^^^^^^^^^^^^^^^^^^^^^^^^^^^^^^^^^^^^
  File "/home/airflow/.local/lib/python3.12/site-packages/airflow/models/taskinstance.py", line 734, in _execute_callable
    return ExecutionCallableRunner(
           ^^^^^^^^^^^^^^^^^^^^^^^^
  File "/home/airflow/.local/lib/python3.12/site-packages/airflow/utils/operator_helpers.py", line 252, in run
    return self.func(*args, **kwargs)
           ^^^^^^^^^^^^^^^^^^^^^^^^^^
  File "/home/airflow/.local/lib/python3.12/site-packages/airflow/models/baseoperator.py", line 424, in wrapper
    return func(self, *args, **kwargs)
           ^^^^^^^^^^^^^^^^^^^^^^^^^^^
  File "/home/airflow/.local/lib/python3.12/site-packages/airflow/operators/python.py", line 238, in execute
    return_value = self.execute_callable()
                   ^^^^^^^^^^^^^^^^^^^^^^^
  File "/home/airflow/.local/lib/python3.12/site-packages/airflow/operators/python.py", line 256, in execute_callable
    return runner.run(*self.op_args, **self.op_kwargs)
           ^^^^^^^^^^^^^^^^^^^^^^^^^^^^^^^^^^^^^^^^^^^
  File "/home/airflow/.local/lib/python3.12/site-packages/airflow/utils/operator_helpers.py", line 252, in run
    return self.func(*args, **kwargs)
           ^^^^^^^^^^^^^^^^^^^^^^^^^^
  File "/opt/airflow/dags/dag.py", line 63, in dvc_push_to_gcs
    raise AirflowFailException(f"❌ DVC push to GCS failed: {e}")
airflow.exceptions.AirflowFailException: ❌ DVC push to GCS failed: Command '['dvc', 'add', '/opt/***/dags/src/scraped_texts']' returned non-zero exit status 253.
[2025-03-02T22:49:58.126+0000] {logging_mixin.py:190} INFO - Task instance in failure state
[2025-03-02T22:49:58.126+0000] {logging_mixin.py:190} INFO - Task start:2025-03-02 22:49:57.061807+00:00 end:2025-03-02 22:49:58.125196+00:00 duration:1.063389
[2025-03-02T22:49:58.126+0000] {logging_mixin.py:190} INFO - Task:<Task(PythonOperator): dvc_push> dag:<DAG: scraping_pipeline_gcs> dagrun:<DagRun scraping_pipeline_gcs @ 2025-03-02 22:49:27.430309+00:00: manual__2025-03-02T22:49:27.430309+00:00, state:running, queued_at: 2025-03-02 22:49:27.509382+00:00. externally triggered: True>
[2025-03-02T22:49:58.127+0000] {logging_mixin.py:190} INFO - Failure caused by ❌ DVC push to GCS failed: Command '['dvc', 'add', '/opt/***/dags/src/scraped_texts']' returned non-zero exit status 253.
[2025-03-02T22:49:58.127+0000] {taskinstance.py:1226} INFO - Immediate failure requested. Marking task as FAILED. dag_id=scraping_pipeline_gcs, task_id=dvc_push, run_id=manual__2025-03-02T22:49:27.430309+00:00, execution_date=20250302T224927, start_date=20250302T224957, end_date=20250302T224958
[2025-03-02T22:49:58.155+0000] {taskinstance.py:341} INFO - ::group::Post task execution logs
[2025-03-02T22:49:58.156+0000] {standard_task_runner.py:124} ERROR - Failed to execute job 177 for task dvc_push (❌ DVC push to GCS failed: Command '['dvc', 'add', '/opt/***/dags/src/scraped_texts']' returned non-zero exit status 253.; 1352)
Traceback (most recent call last):
  File "/opt/airflow/dags/dag.py", line 56, in dvc_push_to_gcs
    subprocess.run(["dvc", "add", SCRAPED_TEXT_DIR], check=True)
  File "/usr/local/lib/python3.12/subprocess.py", line 573, in run
    raise CalledProcessError(retcode, process.args,
subprocess.CalledProcessError: Command '['dvc', 'add', '/opt/airflow/dags/src/scraped_texts']' returned non-zero exit status 253.

During handling of the above exception, another exception occurred:

Traceback (most recent call last):
  File "/home/airflow/.local/lib/python3.12/site-packages/airflow/task/task_runner/standard_task_runner.py", line 117, in _start_by_fork
    ret = args.func(args, dag=self.dag)
          ^^^^^^^^^^^^^^^^^^^^^^^^^^^^^
  File "/home/airflow/.local/lib/python3.12/site-packages/airflow/cli/cli_config.py", line 49, in command
    return func(*args, **kwargs)
           ^^^^^^^^^^^^^^^^^^^^^
  File "/home/airflow/.local/lib/python3.12/site-packages/airflow/utils/cli.py", line 116, in wrapper
    return f(*args, **kwargs)
           ^^^^^^^^^^^^^^^^^^
  File "/home/airflow/.local/lib/python3.12/site-packages/airflow/cli/commands/task_command.py", line 483, in task_run
    task_return_code = _run_task_by_selected_method(args, _dag, ti)
                       ^^^^^^^^^^^^^^^^^^^^^^^^^^^^^^^^^^^^^^^^^^^^
  File "/home/airflow/.local/lib/python3.12/site-packages/airflow/cli/commands/task_command.py", line 256, in _run_task_by_selected_method
    return _run_raw_task(args, ti)
           ^^^^^^^^^^^^^^^^^^^^^^^
  File "/home/airflow/.local/lib/python3.12/site-packages/airflow/cli/commands/task_command.py", line 341, in _run_raw_task
    return ti._run_raw_task(
           ^^^^^^^^^^^^^^^^^
  File "/home/airflow/.local/lib/python3.12/site-packages/airflow/utils/session.py", line 97, in wrapper
    return func(*args, session=session, **kwargs)
           ^^^^^^^^^^^^^^^^^^^^^^^^^^^^^^^^^^^^^^
  File "/home/airflow/.local/lib/python3.12/site-packages/airflow/models/taskinstance.py", line 3006, in _run_raw_task
    return _run_raw_task(
           ^^^^^^^^^^^^^^
  File "/home/airflow/.local/lib/python3.12/site-packages/airflow/models/taskinstance.py", line 274, in _run_raw_task
    TaskInstance._execute_task_with_callbacks(
  File "/home/airflow/.local/lib/python3.12/site-packages/airflow/models/taskinstance.py", line 3161, in _execute_task_with_callbacks
    result = self._execute_task(context, task_orig)
             ^^^^^^^^^^^^^^^^^^^^^^^^^^^^^^^^^^^^^^
  File "/home/airflow/.local/lib/python3.12/site-packages/airflow/models/taskinstance.py", line 3185, in _execute_task
    return _execute_task(self, context, task_orig)
           ^^^^^^^^^^^^^^^^^^^^^^^^^^^^^^^^^^^^^^^
  File "/home/airflow/.local/lib/python3.12/site-packages/airflow/models/taskinstance.py", line 768, in _execute_task
    result = _execute_callable(context=context, **execute_callable_kwargs)
             ^^^^^^^^^^^^^^^^^^^^^^^^^^^^^^^^^^^^^^^^^^^^^^^^^^^^^^^^^^^^^
  File "/home/airflow/.local/lib/python3.12/site-packages/airflow/models/taskinstance.py", line 734, in _execute_callable
    return ExecutionCallableRunner(
           ^^^^^^^^^^^^^^^^^^^^^^^^
  File "/home/airflow/.local/lib/python3.12/site-packages/airflow/utils/operator_helpers.py", line 252, in run
    return self.func(*args, **kwargs)
           ^^^^^^^^^^^^^^^^^^^^^^^^^^
  File "/home/airflow/.local/lib/python3.12/site-packages/airflow/models/baseoperator.py", line 424, in wrapper
    return func(self, *args, **kwargs)
           ^^^^^^^^^^^^^^^^^^^^^^^^^^^
  File "/home/airflow/.local/lib/python3.12/site-packages/airflow/operators/python.py", line 238, in execute
    return_value = self.execute_callable()
                   ^^^^^^^^^^^^^^^^^^^^^^^
  File "/home/airflow/.local/lib/python3.12/site-packages/airflow/operators/python.py", line 256, in execute_callable
    return runner.run(*self.op_args, **self.op_kwargs)
           ^^^^^^^^^^^^^^^^^^^^^^^^^^^^^^^^^^^^^^^^^^^
  File "/home/airflow/.local/lib/python3.12/site-packages/airflow/utils/operator_helpers.py", line 252, in run
    return self.func(*args, **kwargs)
           ^^^^^^^^^^^^^^^^^^^^^^^^^^
  File "/opt/airflow/dags/dag.py", line 63, in dvc_push_to_gcs
    raise AirflowFailException(f"❌ DVC push to GCS failed: {e}")
airflow.exceptions.AirflowFailException: ❌ DVC push to GCS failed: Command '['dvc', 'add', '/opt/***/dags/src/scraped_texts']' returned non-zero exit status 253.
[2025-03-02T22:49:58.203+0000] {local_task_job_runner.py:266} INFO - Task exited with return code 1
[2025-03-02T22:49:58.254+0000] {taskinstance.py:3901} INFO - 1 downstream tasks scheduled from follow-on schedule check
[2025-03-02T22:49:58.257+0000] {local_task_job_runner.py:245} INFO - ::endgroup::
