[2025-03-02T08:21:35.179+0000] {local_task_job_runner.py:123} INFO - ::group::Pre task execution logs
[2025-03-02T08:21:35.237+0000] {taskinstance.py:2614} INFO - Dependencies all met for dep_context=non-requeueable deps ti=<TaskInstance: scraping_pipeline_gcs.run_unittests manual__2025-03-02T08:20:44.403054+00:00 [queued]>
[2025-03-02T08:21:35.264+0000] {taskinstance.py:2614} INFO - Dependencies all met for dep_context=requeueable deps ti=<TaskInstance: scraping_pipeline_gcs.run_unittests manual__2025-03-02T08:20:44.403054+00:00 [queued]>
[2025-03-02T08:21:35.264+0000] {taskinstance.py:2867} INFO - Starting attempt 1 of 3
[2025-03-02T08:21:35.279+0000] {taskinstance.py:2890} INFO - Executing <Task(BashOperator): run_unittests> on 2025-03-02 08:20:44.403054+00:00
[2025-03-02T08:21:35.403+0000] {standard_task_runner.py:104} INFO - Running: ['***', 'tasks', 'run', 'scraping_pipeline_gcs', 'run_unittests', 'manual__2025-03-02T08:20:44.403054+00:00', '--job-id', '57', '--raw', '--subdir', 'DAGS_FOLDER/dag.py', '--cfg-path', '/tmp/tmp9emyl__r']
[2025-03-02T08:21:35.395+0000] {warnings.py:112} WARNING - /home/***/.local/lib/python3.12/site-packages/***/task/task_runner/standard_task_runner.py:70: DeprecationWarning: This process (pid=113) is multi-threaded, use of fork() may lead to deadlocks in the child.
  pid = os.fork()

[2025-03-02T08:21:35.406+0000] {standard_task_runner.py:105} INFO - Job 57: Subtask run_unittests
[2025-03-02T08:21:35.407+0000] {standard_task_runner.py:72} INFO - Started process 115 to run task
[2025-03-02T08:21:35.633+0000] {task_command.py:467} INFO - Running <TaskInstance: scraping_pipeline_gcs.run_unittests manual__2025-03-02T08:20:44.403054+00:00 [running]> on host 8b8ee4ab00d2
[2025-03-02T08:21:41.571+0000] {taskinstance.py:3134} INFO - Exporting env vars: AIRFLOW_CTX_DAG_OWNER='***' AIRFLOW_CTX_DAG_ID='scraping_pipeline_gcs' AIRFLOW_CTX_TASK_ID='run_unittests' AIRFLOW_CTX_EXECUTION_DATE='2025-03-02T08:20:44.403054+00:00' AIRFLOW_CTX_TRY_NUMBER='1' AIRFLOW_CTX_DAG_RUN_ID='manual__2025-03-02T08:20:44.403054+00:00'
[2025-03-02T08:21:41.575+0000] {logging_mixin.py:190} INFO - Task instance is in running state
[2025-03-02T08:21:41.576+0000] {logging_mixin.py:190} INFO -  Previous state of the Task instance: queued
[2025-03-02T08:21:41.576+0000] {logging_mixin.py:190} INFO - Current task name:run_unittests state:running start_date:2025-03-02 08:21:35.237877+00:00
[2025-03-02T08:21:41.576+0000] {logging_mixin.py:190} INFO - Dag name:scraping_pipeline_gcs and current dag run status:running
[2025-03-02T08:21:41.576+0000] {taskinstance.py:732} INFO - ::endgroup::
[2025-03-02T08:21:41.577+0000] {subprocess.py:78} INFO - Tmp dir root location: /tmp
[2025-03-02T08:21:41.581+0000] {subprocess.py:88} INFO - Running command: ['/usr/bin/bash', '-c', 'pytest /opt/***/dags/src/test_scraper.py']
[2025-03-02T08:21:41.647+0000] {subprocess.py:99} INFO - Output:
[2025-03-02T08:21:43.828+0000] {subprocess.py:106} INFO - ============================= test session starts ==============================
[2025-03-02T08:21:43.836+0000] {subprocess.py:106} INFO - platform linux -- Python 3.12.9, pytest-8.3.4, pluggy-1.5.0
[2025-03-02T08:21:43.836+0000] {subprocess.py:106} INFO - rootdir: /opt/***/dags/src
[2025-03-02T08:21:43.838+0000] {subprocess.py:106} INFO - plugins: time-machine-2.16.0, anyio-4.8.0
[2025-03-02T08:21:43.838+0000] {subprocess.py:106} INFO - collected 7 items
[2025-03-02T08:21:43.838+0000] {subprocess.py:106} INFO - 
[2025-03-02T08:21:59.236+0000] {subprocess.py:106} INFO - ../../opt/***/dags/src/test_scraper.py ....F..                       [100%]
[2025-03-02T08:21:59.285+0000] {subprocess.py:106} INFO - 
[2025-03-02T08:21:59.288+0000] {subprocess.py:106} INFO - =================================== FAILURES ===================================
[2025-03-02T08:21:59.290+0000] {subprocess.py:106} INFO - _____________________________ test_start_webdriver _____________________________
[2025-03-02T08:21:59.290+0000] {subprocess.py:106} INFO - 
[2025-03-02T08:21:59.291+0000] {subprocess.py:106} INFO - mock_chrome = <MagicMock name='Chrome' id='281472803354384'>
[2025-03-02T08:21:59.291+0000] {subprocess.py:106} INFO - 
[2025-03-02T08:21:59.297+0000] {subprocess.py:106} INFO -     @patch("Scrape_script.webdriver.Chrome")
[2025-03-02T08:21:59.298+0000] {subprocess.py:106} INFO -     def test_start_webdriver(mock_chrome):
[2025-03-02T08:21:59.299+0000] {subprocess.py:106} INFO -         """Test WebDriver starts correctly."""
[2025-03-02T08:21:59.300+0000] {subprocess.py:106} INFO -         driver = start_webdriver()
[2025-03-02T08:21:59.301+0000] {subprocess.py:106} INFO - >       assert mock_chrome.called
[2025-03-02T08:21:59.302+0000] {subprocess.py:106} INFO - E       AssertionError: assert False
[2025-03-02T08:21:59.304+0000] {subprocess.py:106} INFO - E        +  where False = <MagicMock name='Chrome' id='281472803354384'>.called
[2025-03-02T08:21:59.305+0000] {subprocess.py:106} INFO - 
[2025-03-02T08:21:59.307+0000] {subprocess.py:106} INFO - /opt/***/dags/src/test_scraper.py:105: AssertionError
[2025-03-02T08:21:59.308+0000] {subprocess.py:106} INFO - =============================== warnings summary ===============================
[2025-03-02T08:21:59.309+0000] {subprocess.py:106} INFO - test_scraper.py::test_start_webdriver
[2025-03-02T08:21:59.310+0000] {subprocess.py:106} INFO - test_scraper.py::test_start_webdriver
[2025-03-02T08:21:59.313+0000] {subprocess.py:106} INFO -   /home/***/.local/lib/python3.12/site-packages/urllib3/_request_methods.py:278: DeprecationWarning: URLs without a scheme (ie 'https://') are deprecated and will raise an error in a future version of urllib3. To avoid this DeprecationWarning ensure all URLs start with 'https://' or 'http://'. Read more in this issue: https://github.com/urllib3/urllib3/issues/2920
[2025-03-02T08:21:59.319+0000] {subprocess.py:106} INFO -     return self.urlopen(method, url, **extra_kw)
[2025-03-02T08:21:59.321+0000] {subprocess.py:106} INFO - 
[2025-03-02T08:21:59.322+0000] {subprocess.py:106} INFO - -- Docs: https://docs.pytest.org/en/stable/how-to/capture-warnings.html
[2025-03-02T08:21:59.323+0000] {subprocess.py:106} INFO - =========================== short test summary info ============================
[2025-03-02T08:21:59.326+0000] {subprocess.py:106} INFO - FAILED ../../opt/***/dags/src/test_scraper.py::test_start_webdriver - Ass...
[2025-03-02T08:21:59.328+0000] {subprocess.py:106} INFO - =================== 1 failed, 6 passed, 2 warnings in 16.15s ===================
[2025-03-02T08:21:59.449+0000] {subprocess.py:110} INFO - Command exited with return code 1
[2025-03-02T08:21:59.753+0000] {taskinstance.py:3313} ERROR - Task failed with exception
Traceback (most recent call last):
  File "/home/airflow/.local/lib/python3.12/site-packages/airflow/models/taskinstance.py", line 768, in _execute_task
    result = _execute_callable(context=context, **execute_callable_kwargs)
             ^^^^^^^^^^^^^^^^^^^^^^^^^^^^^^^^^^^^^^^^^^^^^^^^^^^^^^^^^^^^^
  File "/home/airflow/.local/lib/python3.12/site-packages/airflow/models/taskinstance.py", line 734, in _execute_callable
    return ExecutionCallableRunner(
           ^^^^^^^^^^^^^^^^^^^^^^^^
  File "/home/airflow/.local/lib/python3.12/site-packages/airflow/utils/operator_helpers.py", line 252, in run
    return self.func(*args, **kwargs)
           ^^^^^^^^^^^^^^^^^^^^^^^^^^
  File "/home/airflow/.local/lib/python3.12/site-packages/airflow/models/baseoperator.py", line 424, in wrapper
    return func(self, *args, **kwargs)
           ^^^^^^^^^^^^^^^^^^^^^^^^^^^
  File "/home/airflow/.local/lib/python3.12/site-packages/airflow/operators/bash.py", line 276, in execute
    raise AirflowException(
airflow.exceptions.AirflowException: Bash command failed. The command returned a non-zero exit code 1.
[2025-03-02T08:21:59.864+0000] {logging_mixin.py:190} INFO - Task instance in failure state
[2025-03-02T08:21:59.865+0000] {logging_mixin.py:190} INFO - Task start:2025-03-02 08:21:35.237877+00:00 end:2025-03-02 08:21:59.851203+00:00 duration:24.613326
[2025-03-02T08:21:59.867+0000] {logging_mixin.py:190} INFO - Task:<Task(BashOperator): run_unittests> dag:<DAG: scraping_pipeline_gcs> dagrun:<DagRun scraping_pipeline_gcs @ 2025-03-02 08:20:44.403054+00:00: manual__2025-03-02T08:20:44.403054+00:00, state:running, queued_at: 2025-03-02 08:20:44.518527+00:00. externally triggered: True>
[2025-03-02T08:21:59.867+0000] {logging_mixin.py:190} INFO - Failure caused by Bash command failed. The command returned a non-zero exit code 1.
[2025-03-02T08:21:59.869+0000] {taskinstance.py:1226} INFO - Marking task as UP_FOR_RETRY. dag_id=scraping_pipeline_gcs, task_id=run_unittests, run_id=manual__2025-03-02T08:20:44.403054+00:00, execution_date=20250302T082044, start_date=20250302T082135, end_date=20250302T082159
[2025-03-02T08:21:59.994+0000] {taskinstance.py:341} INFO - ::group::Post task execution logs
[2025-03-02T08:22:00.000+0000] {standard_task_runner.py:124} ERROR - Failed to execute job 57 for task run_unittests (Bash command failed. The command returned a non-zero exit code 1.; 115)
Traceback (most recent call last):
  File "/home/airflow/.local/lib/python3.12/site-packages/airflow/task/task_runner/standard_task_runner.py", line 117, in _start_by_fork
    ret = args.func(args, dag=self.dag)
          ^^^^^^^^^^^^^^^^^^^^^^^^^^^^^
  File "/home/airflow/.local/lib/python3.12/site-packages/airflow/cli/cli_config.py", line 49, in command
    return func(*args, **kwargs)
           ^^^^^^^^^^^^^^^^^^^^^
  File "/home/airflow/.local/lib/python3.12/site-packages/airflow/utils/cli.py", line 116, in wrapper
    return f(*args, **kwargs)
           ^^^^^^^^^^^^^^^^^^
  File "/home/airflow/.local/lib/python3.12/site-packages/airflow/cli/commands/task_command.py", line 483, in task_run
    task_return_code = _run_task_by_selected_method(args, _dag, ti)
                       ^^^^^^^^^^^^^^^^^^^^^^^^^^^^^^^^^^^^^^^^^^^^
  File "/home/airflow/.local/lib/python3.12/site-packages/airflow/cli/commands/task_command.py", line 256, in _run_task_by_selected_method
    return _run_raw_task(args, ti)
           ^^^^^^^^^^^^^^^^^^^^^^^
  File "/home/airflow/.local/lib/python3.12/site-packages/airflow/cli/commands/task_command.py", line 341, in _run_raw_task
    return ti._run_raw_task(
           ^^^^^^^^^^^^^^^^^
  File "/home/airflow/.local/lib/python3.12/site-packages/airflow/utils/session.py", line 97, in wrapper
    return func(*args, session=session, **kwargs)
           ^^^^^^^^^^^^^^^^^^^^^^^^^^^^^^^^^^^^^^
  File "/home/airflow/.local/lib/python3.12/site-packages/airflow/models/taskinstance.py", line 3006, in _run_raw_task
    return _run_raw_task(
           ^^^^^^^^^^^^^^
  File "/home/airflow/.local/lib/python3.12/site-packages/airflow/models/taskinstance.py", line 274, in _run_raw_task
    TaskInstance._execute_task_with_callbacks(
  File "/home/airflow/.local/lib/python3.12/site-packages/airflow/models/taskinstance.py", line 3161, in _execute_task_with_callbacks
    result = self._execute_task(context, task_orig)
             ^^^^^^^^^^^^^^^^^^^^^^^^^^^^^^^^^^^^^^
  File "/home/airflow/.local/lib/python3.12/site-packages/airflow/models/taskinstance.py", line 3185, in _execute_task
    return _execute_task(self, context, task_orig)
           ^^^^^^^^^^^^^^^^^^^^^^^^^^^^^^^^^^^^^^^
  File "/home/airflow/.local/lib/python3.12/site-packages/airflow/models/taskinstance.py", line 768, in _execute_task
    result = _execute_callable(context=context, **execute_callable_kwargs)
             ^^^^^^^^^^^^^^^^^^^^^^^^^^^^^^^^^^^^^^^^^^^^^^^^^^^^^^^^^^^^^
  File "/home/airflow/.local/lib/python3.12/site-packages/airflow/models/taskinstance.py", line 734, in _execute_callable
    return ExecutionCallableRunner(
           ^^^^^^^^^^^^^^^^^^^^^^^^
  File "/home/airflow/.local/lib/python3.12/site-packages/airflow/utils/operator_helpers.py", line 252, in run
    return self.func(*args, **kwargs)
           ^^^^^^^^^^^^^^^^^^^^^^^^^^
  File "/home/airflow/.local/lib/python3.12/site-packages/airflow/models/baseoperator.py", line 424, in wrapper
    return func(self, *args, **kwargs)
           ^^^^^^^^^^^^^^^^^^^^^^^^^^^
  File "/home/airflow/.local/lib/python3.12/site-packages/airflow/operators/bash.py", line 276, in execute
    raise AirflowException(
airflow.exceptions.AirflowException: Bash command failed. The command returned a non-zero exit code 1.
[2025-03-02T08:22:00.121+0000] {local_task_job_runner.py:266} INFO - Task exited with return code 1
[2025-03-02T08:22:00.408+0000] {taskinstance.py:3901} INFO - 0 downstream tasks scheduled from follow-on schedule check
[2025-03-02T08:22:00.415+0000] {local_task_job_runner.py:245} INFO - ::endgroup::
