[2025-03-02T16:33:38.188+0000] {local_task_job_runner.py:123} INFO - ::group::Pre task execution logs
[2025-03-02T16:33:38.199+0000] {taskinstance.py:2614} INFO - Dependencies all met for dep_context=non-requeueable deps ti=<TaskInstance: scraping_pipeline_gcs.run_unittests manual__2025-03-02T16:33:29.720388+00:00 [queued]>
[2025-03-02T16:33:38.207+0000] {taskinstance.py:2614} INFO - Dependencies all met for dep_context=requeueable deps ti=<TaskInstance: scraping_pipeline_gcs.run_unittests manual__2025-03-02T16:33:29.720388+00:00 [queued]>
[2025-03-02T16:33:38.207+0000] {taskinstance.py:2867} INFO - Starting attempt 1 of 3
[2025-03-02T16:33:38.214+0000] {taskinstance.py:2890} INFO - Executing <Task(BashOperator): run_unittests> on 2025-03-02 16:33:29.720388+00:00
[2025-03-02T16:33:38.227+0000] {warnings.py:112} WARNING - /home/***/.local/lib/python3.12/site-packages/***/task/task_runner/standard_task_runner.py:70: DeprecationWarning: This process (pid=115) is multi-threaded, use of fork() may lead to deadlocks in the child.
  pid = os.fork()

[2025-03-02T16:33:38.230+0000] {standard_task_runner.py:72} INFO - Started process 117 to run task
[2025-03-02T16:33:38.231+0000] {standard_task_runner.py:104} INFO - Running: ['***', 'tasks', 'run', 'scraping_pipeline_gcs', 'run_unittests', 'manual__2025-03-02T16:33:29.720388+00:00', '--job-id', '134', '--raw', '--subdir', 'DAGS_FOLDER/dag.py', '--cfg-path', '/tmp/tmpffr95akg']
[2025-03-02T16:33:38.232+0000] {standard_task_runner.py:105} INFO - Job 134: Subtask run_unittests
[2025-03-02T16:33:38.285+0000] {task_command.py:467} INFO - Running <TaskInstance: scraping_pipeline_gcs.run_unittests manual__2025-03-02T16:33:29.720388+00:00 [running]> on host 8b8ee4ab00d2
[2025-03-02T16:33:38.667+0000] {taskinstance.py:3134} INFO - Exporting env vars: AIRFLOW_CTX_DAG_OWNER='***' AIRFLOW_CTX_DAG_ID='scraping_pipeline_gcs' AIRFLOW_CTX_TASK_ID='run_unittests' AIRFLOW_CTX_EXECUTION_DATE='2025-03-02T16:33:29.720388+00:00' AIRFLOW_CTX_TRY_NUMBER='1' AIRFLOW_CTX_DAG_RUN_ID='manual__2025-03-02T16:33:29.720388+00:00'
[2025-03-02T16:33:38.668+0000] {logging_mixin.py:190} INFO - Task instance is in running state
[2025-03-02T16:33:38.668+0000] {logging_mixin.py:190} INFO -  Previous state of the Task instance: queued
[2025-03-02T16:33:38.668+0000] {logging_mixin.py:190} INFO - Current task name:run_unittests state:running start_date:2025-03-02 16:33:38.200191+00:00
[2025-03-02T16:33:38.669+0000] {logging_mixin.py:190} INFO - Dag name:scraping_pipeline_gcs and current dag run status:running
[2025-03-02T16:33:38.669+0000] {taskinstance.py:732} INFO - ::endgroup::
[2025-03-02T16:33:38.670+0000] {subprocess.py:78} INFO - Tmp dir root location: /tmp
[2025-03-02T16:33:38.670+0000] {subprocess.py:88} INFO - Running command: ['/usr/bin/bash', '-c', 'pytest /opt/***/dags/src/test_scraper.py']
[2025-03-02T16:33:38.677+0000] {subprocess.py:99} INFO - Output:
[2025-03-02T16:33:40.349+0000] {subprocess.py:106} INFO - ============================= test session starts ==============================
[2025-03-02T16:33:40.355+0000] {subprocess.py:106} INFO - platform linux -- Python 3.12.9, pytest-8.3.4, pluggy-1.5.0
[2025-03-02T16:33:40.356+0000] {subprocess.py:106} INFO - rootdir: /opt/***/dags/src
[2025-03-02T16:33:40.357+0000] {subprocess.py:106} INFO - plugins: time-machine-2.16.0, anyio-4.8.0, hydra-core-1.3.2
[2025-03-02T16:33:40.359+0000] {subprocess.py:106} INFO - collected 0 items / 1 error
[2025-03-02T16:33:40.361+0000] {subprocess.py:106} INFO - 
[2025-03-02T16:33:40.361+0000] {subprocess.py:106} INFO - ==================================== ERRORS ====================================
[2025-03-02T16:33:40.361+0000] {subprocess.py:106} INFO - _______________________ ERROR collecting test_scraper.py _______________________
[2025-03-02T16:33:40.361+0000] {subprocess.py:106} INFO - /opt/***/dags/src/test_scraper.py:14: in <module>
[2025-03-02T16:33:40.361+0000] {subprocess.py:106} INFO -     from Scrape_script import (
[2025-03-02T16:33:40.362+0000] {subprocess.py:106} INFO - /opt/***/dags/src/Scrape_script.py:32: in <module>
[2025-03-02T16:33:40.362+0000] {subprocess.py:106} INFO -     os.mkdir(SCRAPED_TEXT_DIR, exist_ok=True)
[2025-03-02T16:33:40.362+0000] {subprocess.py:106} INFO - E   TypeError: 'exist_ok' is an invalid keyword argument for mkdir()
[2025-03-02T16:33:40.363+0000] {subprocess.py:106} INFO - =========================== short test summary info ============================
[2025-03-02T16:33:40.364+0000] {subprocess.py:106} INFO - ERROR ../../opt/***/dags/src/test_scraper.py - TypeError: 'exist_ok' is a...
[2025-03-02T16:33:40.365+0000] {subprocess.py:106} INFO - !!!!!!!!!!!!!!!!!!!! Interrupted: 1 error during collection !!!!!!!!!!!!!!!!!!!!
[2025-03-02T16:33:40.366+0000] {subprocess.py:106} INFO - =============================== 1 error in 0.53s ===============================
[2025-03-02T16:33:40.423+0000] {subprocess.py:110} INFO - Command exited with return code 2
[2025-03-02T16:33:40.475+0000] {taskinstance.py:3313} ERROR - Task failed with exception
Traceback (most recent call last):
  File "/home/airflow/.local/lib/python3.12/site-packages/airflow/models/taskinstance.py", line 768, in _execute_task
    result = _execute_callable(context=context, **execute_callable_kwargs)
             ^^^^^^^^^^^^^^^^^^^^^^^^^^^^^^^^^^^^^^^^^^^^^^^^^^^^^^^^^^^^^
  File "/home/airflow/.local/lib/python3.12/site-packages/airflow/models/taskinstance.py", line 734, in _execute_callable
    return ExecutionCallableRunner(
           ^^^^^^^^^^^^^^^^^^^^^^^^
  File "/home/airflow/.local/lib/python3.12/site-packages/airflow/utils/operator_helpers.py", line 252, in run
    return self.func(*args, **kwargs)
           ^^^^^^^^^^^^^^^^^^^^^^^^^^
  File "/home/airflow/.local/lib/python3.12/site-packages/airflow/models/baseoperator.py", line 424, in wrapper
    return func(self, *args, **kwargs)
           ^^^^^^^^^^^^^^^^^^^^^^^^^^^
  File "/home/airflow/.local/lib/python3.12/site-packages/airflow/operators/bash.py", line 276, in execute
    raise AirflowException(
airflow.exceptions.AirflowException: Bash command failed. The command returned a non-zero exit code 2.
[2025-03-02T16:33:40.496+0000] {logging_mixin.py:190} INFO - Task instance in failure state
[2025-03-02T16:33:40.496+0000] {logging_mixin.py:190} INFO - Task start:2025-03-02 16:33:38.200191+00:00 end:2025-03-02 16:33:40.495257+00:00 duration:2.295066
[2025-03-02T16:33:40.496+0000] {logging_mixin.py:190} INFO - Task:<Task(BashOperator): run_unittests> dag:<DAG: scraping_pipeline_gcs> dagrun:<DagRun scraping_pipeline_gcs @ 2025-03-02 16:33:29.720388+00:00: manual__2025-03-02T16:33:29.720388+00:00, state:running, queued_at: 2025-03-02 16:33:29.772013+00:00. externally triggered: True>
[2025-03-02T16:33:40.497+0000] {logging_mixin.py:190} INFO - Failure caused by Bash command failed. The command returned a non-zero exit code 2.
[2025-03-02T16:33:40.497+0000] {taskinstance.py:1226} INFO - Marking task as UP_FOR_RETRY. dag_id=scraping_pipeline_gcs, task_id=run_unittests, run_id=manual__2025-03-02T16:33:29.720388+00:00, execution_date=20250302T163329, start_date=20250302T163338, end_date=20250302T163340
[2025-03-02T16:33:40.528+0000] {taskinstance.py:341} INFO - ::group::Post task execution logs
[2025-03-02T16:33:40.528+0000] {standard_task_runner.py:124} ERROR - Failed to execute job 134 for task run_unittests (Bash command failed. The command returned a non-zero exit code 2.; 117)
Traceback (most recent call last):
  File "/home/airflow/.local/lib/python3.12/site-packages/airflow/task/task_runner/standard_task_runner.py", line 117, in _start_by_fork
    ret = args.func(args, dag=self.dag)
          ^^^^^^^^^^^^^^^^^^^^^^^^^^^^^
  File "/home/airflow/.local/lib/python3.12/site-packages/airflow/cli/cli_config.py", line 49, in command
    return func(*args, **kwargs)
           ^^^^^^^^^^^^^^^^^^^^^
  File "/home/airflow/.local/lib/python3.12/site-packages/airflow/utils/cli.py", line 116, in wrapper
    return f(*args, **kwargs)
           ^^^^^^^^^^^^^^^^^^
  File "/home/airflow/.local/lib/python3.12/site-packages/airflow/cli/commands/task_command.py", line 483, in task_run
    task_return_code = _run_task_by_selected_method(args, _dag, ti)
                       ^^^^^^^^^^^^^^^^^^^^^^^^^^^^^^^^^^^^^^^^^^^^
  File "/home/airflow/.local/lib/python3.12/site-packages/airflow/cli/commands/task_command.py", line 256, in _run_task_by_selected_method
    return _run_raw_task(args, ti)
           ^^^^^^^^^^^^^^^^^^^^^^^
  File "/home/airflow/.local/lib/python3.12/site-packages/airflow/cli/commands/task_command.py", line 341, in _run_raw_task
    return ti._run_raw_task(
           ^^^^^^^^^^^^^^^^^
  File "/home/airflow/.local/lib/python3.12/site-packages/airflow/utils/session.py", line 97, in wrapper
    return func(*args, session=session, **kwargs)
           ^^^^^^^^^^^^^^^^^^^^^^^^^^^^^^^^^^^^^^
  File "/home/airflow/.local/lib/python3.12/site-packages/airflow/models/taskinstance.py", line 3006, in _run_raw_task
    return _run_raw_task(
           ^^^^^^^^^^^^^^
  File "/home/airflow/.local/lib/python3.12/site-packages/airflow/models/taskinstance.py", line 274, in _run_raw_task
    TaskInstance._execute_task_with_callbacks(
  File "/home/airflow/.local/lib/python3.12/site-packages/airflow/models/taskinstance.py", line 3161, in _execute_task_with_callbacks
    result = self._execute_task(context, task_orig)
             ^^^^^^^^^^^^^^^^^^^^^^^^^^^^^^^^^^^^^^
  File "/home/airflow/.local/lib/python3.12/site-packages/airflow/models/taskinstance.py", line 3185, in _execute_task
    return _execute_task(self, context, task_orig)
           ^^^^^^^^^^^^^^^^^^^^^^^^^^^^^^^^^^^^^^^
  File "/home/airflow/.local/lib/python3.12/site-packages/airflow/models/taskinstance.py", line 768, in _execute_task
    result = _execute_callable(context=context, **execute_callable_kwargs)
             ^^^^^^^^^^^^^^^^^^^^^^^^^^^^^^^^^^^^^^^^^^^^^^^^^^^^^^^^^^^^^
  File "/home/airflow/.local/lib/python3.12/site-packages/airflow/models/taskinstance.py", line 734, in _execute_callable
    return ExecutionCallableRunner(
           ^^^^^^^^^^^^^^^^^^^^^^^^
  File "/home/airflow/.local/lib/python3.12/site-packages/airflow/utils/operator_helpers.py", line 252, in run
    return self.func(*args, **kwargs)
           ^^^^^^^^^^^^^^^^^^^^^^^^^^
  File "/home/airflow/.local/lib/python3.12/site-packages/airflow/models/baseoperator.py", line 424, in wrapper
    return func(self, *args, **kwargs)
           ^^^^^^^^^^^^^^^^^^^^^^^^^^^
  File "/home/airflow/.local/lib/python3.12/site-packages/airflow/operators/bash.py", line 276, in execute
    raise AirflowException(
airflow.exceptions.AirflowException: Bash command failed. The command returned a non-zero exit code 2.
[2025-03-02T16:33:40.548+0000] {local_task_job_runner.py:266} INFO - Task exited with return code 1
[2025-03-02T16:33:40.600+0000] {taskinstance.py:3901} INFO - 0 downstream tasks scheduled from follow-on schedule check
[2025-03-02T16:33:40.601+0000] {local_task_job_runner.py:245} INFO - ::endgroup::
