[2025-03-02T09:45:23.699+0000] {local_task_job_runner.py:123} INFO - ::group::Pre task execution logs
[2025-03-02T09:45:23.734+0000] {taskinstance.py:2614} INFO - Dependencies all met for dep_context=non-requeueable deps ti=<TaskInstance: scraping_pipeline_gcs.extract_data manual__2025-03-02T09:44:57.083679+00:00 [queued]>
[2025-03-02T09:45:23.751+0000] {taskinstance.py:2614} INFO - Dependencies all met for dep_context=requeueable deps ti=<TaskInstance: scraping_pipeline_gcs.extract_data manual__2025-03-02T09:44:57.083679+00:00 [queued]>
[2025-03-02T09:45:23.751+0000] {taskinstance.py:2867} INFO - Starting attempt 1 of 3
[2025-03-02T09:45:23.774+0000] {taskinstance.py:2890} INFO - Executing <Task(BashOperator): extract_data> on 2025-03-02 09:44:57.083679+00:00
[2025-03-02T09:45:23.803+0000] {warnings.py:112} WARNING - /home/***/.local/lib/python3.12/site-packages/***/task/task_runner/standard_task_runner.py:70: DeprecationWarning: This process (pid=1429) is multi-threaded, use of fork() may lead to deadlocks in the child.
  pid = os.fork()

[2025-03-02T09:45:23.807+0000] {standard_task_runner.py:72} INFO - Started process 1433 to run task
[2025-03-02T09:45:23.807+0000] {standard_task_runner.py:104} INFO - Running: ['***', 'tasks', 'run', 'scraping_pipeline_gcs', 'extract_data', 'manual__2025-03-02T09:44:57.083679+00:00', '--job-id', '83', '--raw', '--subdir', 'DAGS_FOLDER/dag.py', '--cfg-path', '/tmp/tmp8wh1xtow']
[2025-03-02T09:45:23.814+0000] {standard_task_runner.py:105} INFO - Job 83: Subtask extract_data
[2025-03-02T09:45:23.975+0000] {task_command.py:467} INFO - Running <TaskInstance: scraping_pipeline_gcs.extract_data manual__2025-03-02T09:44:57.083679+00:00 [running]> on host 8b8ee4ab00d2
[2025-03-02T09:45:27.204+0000] {taskinstance.py:3134} INFO - Exporting env vars: AIRFLOW_CTX_DAG_OWNER='***' AIRFLOW_CTX_DAG_ID='scraping_pipeline_gcs' AIRFLOW_CTX_TASK_ID='extract_data' AIRFLOW_CTX_EXECUTION_DATE='2025-03-02T09:44:57.083679+00:00' AIRFLOW_CTX_TRY_NUMBER='1' AIRFLOW_CTX_DAG_RUN_ID='manual__2025-03-02T09:44:57.083679+00:00'
[2025-03-02T09:45:27.210+0000] {logging_mixin.py:190} INFO - Task instance is in running state
[2025-03-02T09:45:27.211+0000] {logging_mixin.py:190} INFO -  Previous state of the Task instance: queued
[2025-03-02T09:45:27.211+0000] {logging_mixin.py:190} INFO - Current task name:extract_data state:running start_date:2025-03-02 09:45:23.734774+00:00
[2025-03-02T09:45:27.214+0000] {logging_mixin.py:190} INFO - Dag name:scraping_pipeline_gcs and current dag run status:running
[2025-03-02T09:45:27.215+0000] {taskinstance.py:732} INFO - ::endgroup::
[2025-03-02T09:45:27.218+0000] {subprocess.py:78} INFO - Tmp dir root location: /tmp
[2025-03-02T09:45:27.222+0000] {subprocess.py:88} INFO - Running command: ['/usr/bin/bash', '-c', 'cd /opt/***/dags/src && python Scrape_script.py && true']
[2025-03-02T09:45:27.286+0000] {subprocess.py:99} INFO - Output:
[2025-03-02T09:49:45.714+0000] {subprocess.py:106} INFO - [INFO] Visiting: https://www.recreation.northeastern.edu/ (fail_count=0)
[2025-03-02T09:50:06.217+0000] {subprocess.py:106} INFO - [SUCCESS] Scraped: https://www.recreation.northeastern.edu/
[2025-03-02T09:57:09.959+0000] {job.py:229} INFO - Heartbeat recovered after 389.25 seconds
[2025-03-02T09:57:18.562+0000] {subprocess.py:106} INFO - [FATAL ERROR] Message: Could not start a new session. Timed out creating session
[2025-03-02T09:57:18.573+0000] {subprocess.py:106} INFO - Host info: host: 'fe63a5db6cbe', ip: '172.19.0.2'
[2025-03-02T09:57:18.575+0000] {subprocess.py:106} INFO - Build info: version: '4.20.0', revision: '866c76ca80'
[2025-03-02T09:57:18.576+0000] {subprocess.py:106} INFO - System info: os.name: 'Linux', os.arch: 'aarch64', os.version: '6.10.14-linuxkit', java.version: '17.0.11'
[2025-03-02T09:57:18.577+0000] {subprocess.py:106} INFO - Driver info: driver.version: unknown
[2025-03-02T09:57:18.578+0000] {subprocess.py:106} INFO - Stacktrace:
[2025-03-02T09:57:18.579+0000] {subprocess.py:106} INFO -     at org.openqa.selenium.grid.sessionqueue.local.LocalNewSessionQueue.failDueToTimeout (LocalNewSessionQueue.java:461)
[2025-03-02T09:57:18.579+0000] {subprocess.py:106} INFO -     at java.lang.Iterable.forEach (None:-1)
[2025-03-02T09:57:18.579+0000] {subprocess.py:106} INFO -     at org.openqa.selenium.grid.sessionqueue.local.LocalNewSessionQueue.timeoutSessions (LocalNewSessionQueue.java:181)
[2025-03-02T09:57:18.580+0000] {subprocess.py:106} INFO -     at org.openqa.selenium.concurrent.GuardedRunnable.lambda$guard$0 (GuardedRunnable.java:35)
[2025-03-02T09:57:18.580+0000] {subprocess.py:106} INFO -     at java.util.concurrent.Executors$RunnableAdapter.call (None:-1)
[2025-03-02T09:57:18.581+0000] {subprocess.py:106} INFO -     at java.util.concurrent.FutureTask.runAndReset (None:-1)
[2025-03-02T09:57:18.581+0000] {subprocess.py:106} INFO -     at java.util.concurrent.ScheduledThreadPoolExecutor$ScheduledFutureTask.run (None:-1)
[2025-03-02T09:57:18.581+0000] {subprocess.py:106} INFO -     at java.util.concurrent.ThreadPoolExecutor.runWorker (None:-1)
[2025-03-02T09:57:18.582+0000] {subprocess.py:106} INFO -     at java.util.concurrent.ThreadPoolExecutor$Worker.run (None:-1)
[2025-03-02T09:57:18.582+0000] {subprocess.py:106} INFO -     at java.lang.Thread.run (None:-1)
[2025-03-02T09:57:18.619+0000] {subprocess.py:106} INFO - Traceback (most recent call last):
[2025-03-02T09:57:18.620+0000] {subprocess.py:106} INFO -   File "/opt/***/dags/src/Scrape_script.py", line 328, in main
[2025-03-02T09:57:18.624+0000] {subprocess.py:106} INFO -     crawl_dfs_stack(START_URL)
[2025-03-02T09:57:18.624+0000] {subprocess.py:106} INFO -   File "/opt/***/dags/src/Scrape_script.py", line 313, in crawl_dfs_stack
[2025-03-02T09:57:18.624+0000] {subprocess.py:106} INFO -     close_and_new_driver()
[2025-03-02T09:57:18.625+0000] {subprocess.py:106} INFO -   File "/opt/***/dags/src/Scrape_script.py", line 152, in close_and_new_driver
[2025-03-02T09:57:18.628+0000] {subprocess.py:106} INFO -     driver = start_webdriver(current_proxy)
[2025-03-02T09:57:18.628+0000] {subprocess.py:106} INFO -              ^^^^^^^^^^^^^^^^^^^^^^^^^^^^^^
[2025-03-02T09:57:18.628+0000] {subprocess.py:106} INFO -   File "/opt/***/dags/src/Scrape_script.py", line 130, in start_webdriver
[2025-03-02T09:57:18.629+0000] {subprocess.py:106} INFO -     driver_ = webdriver.Remote(f"{remote_webdriver}:4444/wd/hub", options=options)
[2025-03-02T09:57:18.629+0000] {subprocess.py:106} INFO -               ^^^^^^^^^^^^^^^^^^^^^^^^^^^^^^^^^^^^^^^^^^^^^^^^^^^^^^^^^^^^^^^^^^^^
[2025-03-02T09:57:18.629+0000] {subprocess.py:106} INFO -   File "/home/***/.local/lib/python3.12/site-packages/selenium/webdriver/remote/webdriver.py", line 250, in __init__
[2025-03-02T09:57:18.631+0000] {subprocess.py:106} INFO -     self.start_session(capabilities)
[2025-03-02T09:57:18.631+0000] {subprocess.py:106} INFO -   File "/home/***/.local/lib/python3.12/site-packages/selenium/webdriver/remote/webdriver.py", line 342, in start_session
[2025-03-02T09:57:18.631+0000] {subprocess.py:106} INFO -     response = self.execute(Command.NEW_SESSION, caps)["value"]
[2025-03-02T09:57:18.633+0000] {subprocess.py:106} INFO -                ^^^^^^^^^^^^^^^^^^^^^^^^^^^^^^^^^^^^^^^
[2025-03-02T09:57:18.634+0000] {subprocess.py:106} INFO -   File "/home/***/.local/lib/python3.12/site-packages/selenium/webdriver/remote/webdriver.py", line 429, in execute
[2025-03-02T09:57:18.635+0000] {subprocess.py:106} INFO -     self.error_handler.check_response(response)
[2025-03-02T09:57:18.636+0000] {subprocess.py:106} INFO -   File "/home/***/.local/lib/python3.12/site-packages/selenium/webdriver/remote/errorhandler.py", line 232, in check_response
[2025-03-02T09:57:18.637+0000] {subprocess.py:106} INFO -     raise exception_class(message, screen, stacktrace)
[2025-03-02T09:57:18.638+0000] {subprocess.py:106} INFO - selenium.common.exceptions.SessionNotCreatedException: Message: Could not start a new session. Timed out creating session
[2025-03-02T09:57:18.638+0000] {subprocess.py:106} INFO - Host info: host: 'fe63a5db6cbe', ip: '172.19.0.2'
[2025-03-02T09:57:18.639+0000] {subprocess.py:106} INFO - Build info: version: '4.20.0', revision: '866c76ca80'
[2025-03-02T09:57:18.639+0000] {subprocess.py:106} INFO - System info: os.name: 'Linux', os.arch: 'aarch64', os.version: '6.10.14-linuxkit', java.version: '17.0.11'
[2025-03-02T09:57:18.640+0000] {subprocess.py:106} INFO - Driver info: driver.version: unknown
[2025-03-02T09:57:18.640+0000] {subprocess.py:106} INFO - Stacktrace:
[2025-03-02T09:57:18.640+0000] {subprocess.py:106} INFO -     at org.openqa.selenium.grid.sessionqueue.local.LocalNewSessionQueue.failDueToTimeout (LocalNewSessionQueue.java:461)
[2025-03-02T09:57:18.641+0000] {subprocess.py:106} INFO -     at java.lang.Iterable.forEach (None:-1)
[2025-03-02T09:57:18.642+0000] {subprocess.py:106} INFO -     at org.openqa.selenium.grid.sessionqueue.local.LocalNewSessionQueue.timeoutSessions (LocalNewSessionQueue.java:181)
[2025-03-02T09:57:18.642+0000] {subprocess.py:106} INFO -     at org.openqa.selenium.concurrent.GuardedRunnable.lambda$guard$0 (GuardedRunnable.java:35)
[2025-03-02T09:57:18.643+0000] {subprocess.py:106} INFO -     at java.util.concurrent.Executors$RunnableAdapter.call (None:-1)
[2025-03-02T09:57:18.643+0000] {subprocess.py:106} INFO -     at java.util.concurrent.FutureTask.runAndReset (None:-1)
[2025-03-02T09:57:18.643+0000] {subprocess.py:106} INFO -     at java.util.concurrent.ScheduledThreadPoolExecutor$ScheduledFutureTask.run (None:-1)
[2025-03-02T09:57:18.643+0000] {subprocess.py:106} INFO -     at java.util.concurrent.ThreadPoolExecutor.runWorker (None:-1)
[2025-03-02T09:57:18.643+0000] {subprocess.py:106} INFO -     at java.util.concurrent.ThreadPoolExecutor$Worker.run (None:-1)
[2025-03-02T09:57:18.644+0000] {subprocess.py:106} INFO -     at java.lang.Thread.run (None:-1)
[2025-03-02T09:57:18.644+0000] {subprocess.py:106} INFO - 
[2025-03-02T09:57:18.644+0000] {subprocess.py:106} INFO - During handling of the above exception, another exception occurred:
[2025-03-02T09:57:18.644+0000] {subprocess.py:106} INFO - 
[2025-03-02T09:57:18.644+0000] {subprocess.py:106} INFO - Traceback (most recent call last):
[2025-03-02T09:57:18.644+0000] {subprocess.py:106} INFO -   File "/opt/***/dags/src/Scrape_script.py", line 331, in main
[2025-03-02T09:57:18.645+0000] {subprocess.py:106} INFO -     sys.exit(1)
[2025-03-02T09:57:18.645+0000] {subprocess.py:106} INFO - SystemExit: 1
[2025-03-02T09:57:18.645+0000] {subprocess.py:106} INFO - 
[2025-03-02T09:57:18.646+0000] {subprocess.py:106} INFO - During handling of the above exception, another exception occurred:
[2025-03-02T09:57:18.646+0000] {subprocess.py:106} INFO - 
[2025-03-02T09:57:18.646+0000] {subprocess.py:106} INFO - Traceback (most recent call last):
[2025-03-02T09:57:18.646+0000] {subprocess.py:106} INFO -   File "/opt/***/dags/src/Scrape_script.py", line 340, in <module>
[2025-03-02T09:57:18.646+0000] {subprocess.py:106} INFO -     main()
[2025-03-02T09:57:18.646+0000] {subprocess.py:106} INFO -   File "/opt/***/dags/src/Scrape_script.py", line 334, in main
[2025-03-02T09:57:18.646+0000] {subprocess.py:106} INFO -     driver.quit()
[2025-03-02T09:57:18.647+0000] {subprocess.py:106} INFO -   File "/home/***/.local/lib/python3.12/site-packages/selenium/webdriver/remote/webdriver.py", line 589, in quit
[2025-03-02T09:57:18.647+0000] {subprocess.py:106} INFO -     self.execute(Command.QUIT)
[2025-03-02T09:57:18.647+0000] {subprocess.py:106} INFO -   File "/home/***/.local/lib/python3.12/site-packages/selenium/webdriver/remote/webdriver.py", line 429, in execute
[2025-03-02T09:57:18.647+0000] {subprocess.py:106} INFO -     self.error_handler.check_response(response)
[2025-03-02T09:57:18.647+0000] {subprocess.py:106} INFO -   File "/home/***/.local/lib/python3.12/site-packages/selenium/webdriver/remote/errorhandler.py", line 232, in check_response
[2025-03-02T09:57:18.647+0000] {subprocess.py:106} INFO -     raise exception_class(message, screen, stacktrace)
[2025-03-02T09:57:18.648+0000] {subprocess.py:106} INFO - selenium.common.exceptions.InvalidSessionIdException: Message: Unable to find session with ID: 57c4a9c88c0a6894a78473784d47dc7f
[2025-03-02T09:57:18.648+0000] {subprocess.py:106} INFO - Build info: version: '4.20.0', revision: '866c76ca80'
[2025-03-02T09:57:18.648+0000] {subprocess.py:106} INFO - System info: os.name: 'Linux', os.arch: 'aarch64', os.version: '6.10.14-linuxkit', java.version: '17.0.11'
[2025-03-02T09:57:18.648+0000] {subprocess.py:106} INFO - Driver info: driver.version: unknown
[2025-03-02T09:57:18.648+0000] {subprocess.py:106} INFO - Stacktrace:
[2025-03-02T09:57:18.649+0000] {subprocess.py:106} INFO - org.openqa.selenium.NoSuchSessionException: Unable to find session with ID: 57c4a9c88c0a6894a78473784d47dc7f
[2025-03-02T09:57:18.649+0000] {subprocess.py:106} INFO - Build info: version: '4.20.0', revision: '866c76ca80'
[2025-03-02T09:57:18.649+0000] {subprocess.py:106} INFO - System info: os.name: 'Linux', os.arch: 'aarch64', os.version: '6.10.14-linuxkit', java.version: '17.0.11'
[2025-03-02T09:57:18.649+0000] {subprocess.py:106} INFO - Driver info: driver.version: unknown
[2025-03-02T09:57:18.649+0000] {subprocess.py:106} INFO - 	at org.openqa.selenium.grid.sessionmap.local.LocalSessionMap.get(LocalSessionMap.java:132)
[2025-03-02T09:57:18.649+0000] {subprocess.py:106} INFO - 	at org.openqa.selenium.grid.sessionmap.SessionMap.getUri(SessionMap.java:84)
[2025-03-02T09:57:18.650+0000] {subprocess.py:106} INFO - 	at org.openqa.selenium.grid.router.HandleSession.lambda$loadSessionId$4(HandleSession.java:223)
[2025-03-02T09:57:18.650+0000] {subprocess.py:106} INFO - 	at io.opentelemetry.context.Context.lambda$wrap$2(Context.java:224)
[2025-03-02T09:57:18.650+0000] {subprocess.py:106} INFO - 	at org.openqa.selenium.grid.router.HandleSession.execute(HandleSession.java:180)
[2025-03-02T09:57:18.650+0000] {subprocess.py:106} INFO - 	at org.openqa.selenium.remote.http.Route$PredicatedRoute.handle(Route.java:383)
[2025-03-02T09:57:18.650+0000] {subprocess.py:106} INFO - 	at org.openqa.selenium.remote.http.Route.execute(Route.java:69)
[2025-03-02T09:57:18.650+0000] {subprocess.py:106} INFO - 	at org.openqa.selenium.remote.http.Route$CombinedRoute.handle(Route.java:346)
[2025-03-02T09:57:18.650+0000] {subprocess.py:106} INFO - 	at org.openqa.selenium.remote.http.Route.execute(Route.java:69)
[2025-03-02T09:57:18.650+0000] {subprocess.py:106} INFO - 	at org.openqa.selenium.grid.router.Router.execute(Router.java:87)
[2025-03-02T09:57:18.650+0000] {subprocess.py:106} INFO - 	at org.openqa.selenium.grid.web.EnsureSpecCompliantResponseHeaders.lambda$apply$0(EnsureSpecCompliantResponseHeaders.java:34)
[2025-03-02T09:57:18.650+0000] {subprocess.py:106} INFO - 	at org.openqa.selenium.remote.http.Filter$1.execute(Filter.java:63)
[2025-03-02T09:57:18.651+0000] {subprocess.py:106} INFO - 	at org.openqa.selenium.remote.http.Route$CombinedRoute.handle(Route.java:346)
[2025-03-02T09:57:18.651+0000] {subprocess.py:106} INFO - 	at org.openqa.selenium.remote.http.Route.execute(Route.java:69)
[2025-03-02T09:57:18.651+0000] {subprocess.py:106} INFO - 	at org.openqa.selenium.remote.http.Route$NestedRoute.handle(Route.java:270)
[2025-03-02T09:57:18.651+0000] {subprocess.py:106} INFO - 	at org.openqa.selenium.remote.http.Route.execute(Route.java:69)
[2025-03-02T09:57:18.651+0000] {subprocess.py:106} INFO - 	at org.openqa.selenium.remote.http.Route$CombinedRoute.handle(Route.java:346)
[2025-03-02T09:57:18.652+0000] {subprocess.py:106} INFO - 	at org.openqa.selenium.remote.http.Route.execute(Route.java:69)
[2025-03-02T09:57:18.652+0000] {subprocess.py:106} INFO - 	at org.openqa.selenium.remote.http.Route$CombinedRoute.handle(Route.java:346)
[2025-03-02T09:57:18.653+0000] {subprocess.py:106} INFO - 	at org.openqa.selenium.remote.http.Route.execute(Route.java:69)
[2025-03-02T09:57:18.654+0000] {subprocess.py:106} INFO - 	at org.openqa.selenium.remote.http.Route$CombinedRoute.handle(Route.java:346)
[2025-03-02T09:57:18.654+0000] {subprocess.py:106} INFO - 	at org.openqa.selenium.remote.http.Route.execute(Route.java:69)
[2025-03-02T09:57:18.654+0000] {subprocess.py:106} INFO - 	at org.openqa.selenium.remote.http.Route$CombinedRoute.handle(Route.java:346)
[2025-03-02T09:57:18.654+0000] {subprocess.py:106} INFO - 	at org.openqa.selenium.remote.http.Route.execute(Route.java:69)
[2025-03-02T09:57:18.654+0000] {subprocess.py:106} INFO - 	at org.openqa.selenium.remote.AddWebDriverSpecHeaders.lambda$apply$0(AddWebDriverSpecHeaders.java:35)
[2025-03-02T09:57:18.655+0000] {subprocess.py:106} INFO - 	at org.openqa.selenium.remote.ErrorFilter.lambda$apply$0(ErrorFilter.java:44)
[2025-03-02T09:57:18.655+0000] {subprocess.py:106} INFO - 	at org.openqa.selenium.remote.http.Filter$1.execute(Filter.java:63)
[2025-03-02T09:57:18.655+0000] {subprocess.py:106} INFO - 	at org.openqa.selenium.remote.ErrorFilter.lambda$apply$0(ErrorFilter.java:44)
[2025-03-02T09:57:18.655+0000] {subprocess.py:106} INFO - 	at org.openqa.selenium.remote.http.Filter$1.execute(Filter.java:63)
[2025-03-02T09:57:18.656+0000] {subprocess.py:106} INFO - 	at org.openqa.selenium.netty.server.SeleniumHandler.lambda$channelRead0$0(SeleniumHandler.java:44)
[2025-03-02T09:57:18.656+0000] {subprocess.py:106} INFO - 	at java.base/java.util.concurrent.Executors$RunnableAdapter.call(Unknown Source)
[2025-03-02T09:57:18.656+0000] {subprocess.py:106} INFO - 	at java.base/java.util.concurrent.FutureTask.run(Unknown Source)
[2025-03-02T09:57:18.656+0000] {subprocess.py:106} INFO - 	at java.base/java.util.concurrent.ThreadPoolExecutor.runWorker(Unknown Source)
[2025-03-02T09:57:18.656+0000] {subprocess.py:106} INFO - 	at java.base/java.util.concurrent.ThreadPoolExecutor$Worker.run(Unknown Source)
[2025-03-02T09:57:18.656+0000] {subprocess.py:106} INFO - 	at java.base/java.lang.Thread.run(Unknown Source)
[2025-03-02T09:57:18.656+0000] {subprocess.py:106} INFO - 
[2025-03-02T09:57:18.812+0000] {subprocess.py:110} INFO - Command exited with return code 1
[2025-03-02T09:57:18.934+0000] {taskinstance.py:3313} ERROR - Task failed with exception
Traceback (most recent call last):
  File "/home/airflow/.local/lib/python3.12/site-packages/airflow/models/taskinstance.py", line 768, in _execute_task
    result = _execute_callable(context=context, **execute_callable_kwargs)
             ^^^^^^^^^^^^^^^^^^^^^^^^^^^^^^^^^^^^^^^^^^^^^^^^^^^^^^^^^^^^^
  File "/home/airflow/.local/lib/python3.12/site-packages/airflow/models/taskinstance.py", line 734, in _execute_callable
    return ExecutionCallableRunner(
           ^^^^^^^^^^^^^^^^^^^^^^^^
  File "/home/airflow/.local/lib/python3.12/site-packages/airflow/utils/operator_helpers.py", line 252, in run
    return self.func(*args, **kwargs)
           ^^^^^^^^^^^^^^^^^^^^^^^^^^
  File "/home/airflow/.local/lib/python3.12/site-packages/airflow/models/baseoperator.py", line 424, in wrapper
    return func(self, *args, **kwargs)
           ^^^^^^^^^^^^^^^^^^^^^^^^^^^
  File "/home/airflow/.local/lib/python3.12/site-packages/airflow/operators/bash.py", line 276, in execute
    raise AirflowException(
airflow.exceptions.AirflowException: Bash command failed. The command returned a non-zero exit code 1.
[2025-03-02T09:57:18.971+0000] {logging_mixin.py:190} INFO - Task instance in failure state
[2025-03-02T09:57:18.972+0000] {logging_mixin.py:190} INFO - Task start:2025-03-02 09:45:23.734774+00:00 end:2025-03-02 09:57:18.966174+00:00 duration:715.2314
[2025-03-02T09:57:18.974+0000] {logging_mixin.py:190} INFO - Task:<Task(BashOperator): extract_data> dag:<DAG: scraping_pipeline_gcs> dagrun:<DagRun scraping_pipeline_gcs @ 2025-03-02 09:44:57.083679+00:00: manual__2025-03-02T09:44:57.083679+00:00, state:running, queued_at: 2025-03-02 09:44:57.132940+00:00. externally triggered: True>
[2025-03-02T09:57:18.974+0000] {logging_mixin.py:190} INFO - Failure caused by Bash command failed. The command returned a non-zero exit code 1.
[2025-03-02T09:57:18.974+0000] {taskinstance.py:1226} INFO - Marking task as UP_FOR_RETRY. dag_id=scraping_pipeline_gcs, task_id=extract_data, run_id=manual__2025-03-02T09:44:57.083679+00:00, execution_date=20250302T094457, start_date=20250302T094523, end_date=20250302T095718
[2025-03-02T09:57:19.026+0000] {taskinstance.py:341} INFO - ::group::Post task execution logs
[2025-03-02T09:57:19.027+0000] {standard_task_runner.py:124} ERROR - Failed to execute job 83 for task extract_data (Bash command failed. The command returned a non-zero exit code 1.; 1433)
Traceback (most recent call last):
  File "/home/airflow/.local/lib/python3.12/site-packages/airflow/task/task_runner/standard_task_runner.py", line 117, in _start_by_fork
    ret = args.func(args, dag=self.dag)
          ^^^^^^^^^^^^^^^^^^^^^^^^^^^^^
  File "/home/airflow/.local/lib/python3.12/site-packages/airflow/cli/cli_config.py", line 49, in command
    return func(*args, **kwargs)
           ^^^^^^^^^^^^^^^^^^^^^
  File "/home/airflow/.local/lib/python3.12/site-packages/airflow/utils/cli.py", line 116, in wrapper
    return f(*args, **kwargs)
           ^^^^^^^^^^^^^^^^^^
  File "/home/airflow/.local/lib/python3.12/site-packages/airflow/cli/commands/task_command.py", line 483, in task_run
    task_return_code = _run_task_by_selected_method(args, _dag, ti)
                       ^^^^^^^^^^^^^^^^^^^^^^^^^^^^^^^^^^^^^^^^^^^^
  File "/home/airflow/.local/lib/python3.12/site-packages/airflow/cli/commands/task_command.py", line 256, in _run_task_by_selected_method
    return _run_raw_task(args, ti)
           ^^^^^^^^^^^^^^^^^^^^^^^
  File "/home/airflow/.local/lib/python3.12/site-packages/airflow/cli/commands/task_command.py", line 341, in _run_raw_task
    return ti._run_raw_task(
           ^^^^^^^^^^^^^^^^^
  File "/home/airflow/.local/lib/python3.12/site-packages/airflow/utils/session.py", line 97, in wrapper
    return func(*args, session=session, **kwargs)
           ^^^^^^^^^^^^^^^^^^^^^^^^^^^^^^^^^^^^^^
  File "/home/airflow/.local/lib/python3.12/site-packages/airflow/models/taskinstance.py", line 3006, in _run_raw_task
    return _run_raw_task(
           ^^^^^^^^^^^^^^
  File "/home/airflow/.local/lib/python3.12/site-packages/airflow/models/taskinstance.py", line 274, in _run_raw_task
    TaskInstance._execute_task_with_callbacks(
  File "/home/airflow/.local/lib/python3.12/site-packages/airflow/models/taskinstance.py", line 3161, in _execute_task_with_callbacks
    result = self._execute_task(context, task_orig)
             ^^^^^^^^^^^^^^^^^^^^^^^^^^^^^^^^^^^^^^
  File "/home/airflow/.local/lib/python3.12/site-packages/airflow/models/taskinstance.py", line 3185, in _execute_task
    return _execute_task(self, context, task_orig)
           ^^^^^^^^^^^^^^^^^^^^^^^^^^^^^^^^^^^^^^^
  File "/home/airflow/.local/lib/python3.12/site-packages/airflow/models/taskinstance.py", line 768, in _execute_task
    result = _execute_callable(context=context, **execute_callable_kwargs)
             ^^^^^^^^^^^^^^^^^^^^^^^^^^^^^^^^^^^^^^^^^^^^^^^^^^^^^^^^^^^^^
  File "/home/airflow/.local/lib/python3.12/site-packages/airflow/models/taskinstance.py", line 734, in _execute_callable
    return ExecutionCallableRunner(
           ^^^^^^^^^^^^^^^^^^^^^^^^
  File "/home/airflow/.local/lib/python3.12/site-packages/airflow/utils/operator_helpers.py", line 252, in run
    return self.func(*args, **kwargs)
           ^^^^^^^^^^^^^^^^^^^^^^^^^^
  File "/home/airflow/.local/lib/python3.12/site-packages/airflow/models/baseoperator.py", line 424, in wrapper
    return func(self, *args, **kwargs)
           ^^^^^^^^^^^^^^^^^^^^^^^^^^^
  File "/home/airflow/.local/lib/python3.12/site-packages/airflow/operators/bash.py", line 276, in execute
    raise AirflowException(
airflow.exceptions.AirflowException: Bash command failed. The command returned a non-zero exit code 1.
[2025-03-02T09:57:19.093+0000] {local_task_job_runner.py:266} INFO - Task exited with return code 1
[2025-03-02T09:57:20.598+0000] {taskinstance.py:3901} INFO - 0 downstream tasks scheduled from follow-on schedule check
[2025-03-02T09:57:20.601+0000] {local_task_job_runner.py:245} INFO - ::endgroup::
