[2025-03-03T00:58:02.045+0000] {local_task_job_runner.py:123} INFO - ::group::Pre task execution logs
[2025-03-03T00:58:02.064+0000] {taskinstance.py:2614} INFO - Dependencies all met for dep_context=non-requeueable deps ti=<TaskInstance: scraping_pipeline_gcs.dvc_push manual__2025-03-03T00:44:58.016740+00:00 [queued]>
[2025-03-03T00:58:02.071+0000] {taskinstance.py:2614} INFO - Dependencies all met for dep_context=requeueable deps ti=<TaskInstance: scraping_pipeline_gcs.dvc_push manual__2025-03-03T00:44:58.016740+00:00 [queued]>
[2025-03-03T00:58:02.071+0000] {taskinstance.py:2867} INFO - Starting attempt 2 of 3
[2025-03-03T00:58:02.084+0000] {taskinstance.py:2890} INFO - Executing <Task(PythonOperator): dvc_push> on 2025-03-03 00:44:58.016740+00:00
[2025-03-03T00:58:02.103+0000] {warnings.py:112} WARNING - /home/***/.local/lib/python3.12/site-packages/***/task/task_runner/standard_task_runner.py:70: DeprecationWarning: This process (pid=1245) is multi-threaded, use of fork() may lead to deadlocks in the child.
  pid = os.fork()

[2025-03-03T00:58:02.108+0000] {standard_task_runner.py:72} INFO - Started process 1247 to run task
[2025-03-03T00:58:02.113+0000] {standard_task_runner.py:104} INFO - Running: ['***', 'tasks', 'run', 'scraping_pipeline_gcs', 'dvc_push', 'manual__2025-03-03T00:44:58.016740+00:00', '--job-id', '261', '--raw', '--subdir', 'DAGS_FOLDER/dag.py', '--cfg-path', '/tmp/tmpdk637mlu']
[2025-03-03T00:58:02.117+0000] {standard_task_runner.py:105} INFO - Job 261: Subtask dvc_push
[2025-03-03T00:58:02.191+0000] {task_command.py:467} INFO - Running <TaskInstance: scraping_pipeline_gcs.dvc_push manual__2025-03-03T00:44:58.016740+00:00 [running]> on host 5e87a20f9330
[2025-03-03T00:58:02.263+0000] {taskinstance.py:3134} INFO - Exporting env vars: AIRFLOW_CTX_DAG_OWNER='***' AIRFLOW_CTX_DAG_ID='scraping_pipeline_gcs' AIRFLOW_CTX_TASK_ID='dvc_push' AIRFLOW_CTX_EXECUTION_DATE='2025-03-03T00:44:58.016740+00:00' AIRFLOW_CTX_TRY_NUMBER='2' AIRFLOW_CTX_DAG_RUN_ID='manual__2025-03-03T00:44:58.016740+00:00'
[2025-03-03T00:58:02.264+0000] {logging_mixin.py:190} INFO - Task instance is in running state
[2025-03-03T00:58:02.265+0000] {logging_mixin.py:190} INFO -  Previous state of the Task instance: queued
[2025-03-03T00:58:02.265+0000] {logging_mixin.py:190} INFO - Current task name:dvc_push state:running start_date:2025-03-03 00:58:02.064582+00:00
[2025-03-03T00:58:02.265+0000] {logging_mixin.py:190} INFO - Dag name:scraping_pipeline_gcs and current dag run status:running
[2025-03-03T00:58:02.265+0000] {taskinstance.py:732} INFO - ::endgroup::
[2025-03-03T00:58:02.267+0000] {taskinstance.py:3313} ERROR - Task failed with exception
Traceback (most recent call last):
  File "/home/airflow/.local/lib/python3.12/site-packages/airflow/models/taskinstance.py", line 768, in _execute_task
    result = _execute_callable(context=context, **execute_callable_kwargs)
             ^^^^^^^^^^^^^^^^^^^^^^^^^^^^^^^^^^^^^^^^^^^^^^^^^^^^^^^^^^^^^
  File "/home/airflow/.local/lib/python3.12/site-packages/airflow/models/taskinstance.py", line 734, in _execute_callable
    return ExecutionCallableRunner(
           ^^^^^^^^^^^^^^^^^^^^^^^^
  File "/home/airflow/.local/lib/python3.12/site-packages/airflow/utils/operator_helpers.py", line 252, in run
    return self.func(*args, **kwargs)
           ^^^^^^^^^^^^^^^^^^^^^^^^^^
  File "/home/airflow/.local/lib/python3.12/site-packages/airflow/models/baseoperator.py", line 424, in wrapper
    return func(self, *args, **kwargs)
           ^^^^^^^^^^^^^^^^^^^^^^^^^^^
  File "/home/airflow/.local/lib/python3.12/site-packages/airflow/operators/python.py", line 238, in execute
    return_value = self.execute_callable()
                   ^^^^^^^^^^^^^^^^^^^^^^^
  File "/home/airflow/.local/lib/python3.12/site-packages/airflow/operators/python.py", line 256, in execute_callable
    return runner.run(*self.op_args, **self.op_kwargs)
           ^^^^^^^^^^^^^^^^^^^^^^^^^^^^^^^^^^^^^^^^^^^
  File "/home/airflow/.local/lib/python3.12/site-packages/airflow/utils/operator_helpers.py", line 252, in run
    return self.func(*args, **kwargs)
           ^^^^^^^^^^^^^^^^^^^^^^^^^^
  File "/opt/airflow/dags/dag.py", line 48, in dvc_push_to_gcs
    subprocess.run(
  File "/usr/local/lib/python3.12/subprocess.py", line 550, in run
    with Popen(*popenargs, **kwargs) as process:
         ^^^^^^^^^^^^^^^^^^^^^^^^^^^
  File "/usr/local/lib/python3.12/subprocess.py", line 1028, in __init__
    self._execute_child(args, executable, preexec_fn, close_fds,
  File "/usr/local/lib/python3.12/subprocess.py", line 1963, in _execute_child
    raise child_exception_type(errno_num, err_msg, err_filename)
FileNotFoundError: [Errno 2] No such file or directory: 'GOOGLE_APPLICATION_CREDENTIALS=./opt/airflow/dags/src/gcs_creds.json'
[2025-03-03T00:58:02.278+0000] {logging_mixin.py:190} INFO - Task instance in failure state
[2025-03-03T00:58:02.278+0000] {logging_mixin.py:190} INFO - Task start:2025-03-03 00:58:02.064582+00:00 end:2025-03-03 00:58:02.277769+00:00 duration:0.213187
[2025-03-03T00:58:02.278+0000] {logging_mixin.py:190} INFO - Task:<Task(PythonOperator): dvc_push> dag:<DAG: scraping_pipeline_gcs> dagrun:<DagRun scraping_pipeline_gcs @ 2025-03-03 00:44:58.016740+00:00: manual__2025-03-03T00:44:58.016740+00:00, state:running, queued_at: 2025-03-03 00:44:58.560045+00:00. externally triggered: True>
[2025-03-03T00:58:02.278+0000] {logging_mixin.py:190} INFO - Failure caused by [Errno 2] No such file or directory: 'GOOGLE_APPLICATION_CREDENTIALS=./opt/***/dags/src/gcs_creds.json'
[2025-03-03T00:58:02.279+0000] {taskinstance.py:1226} INFO - Marking task as UP_FOR_RETRY. dag_id=scraping_pipeline_gcs, task_id=dvc_push, run_id=manual__2025-03-03T00:44:58.016740+00:00, execution_date=20250303T004458, start_date=20250303T005802, end_date=20250303T005802
[2025-03-03T00:58:02.301+0000] {taskinstance.py:341} INFO - ::group::Post task execution logs
[2025-03-03T00:58:02.301+0000] {standard_task_runner.py:124} ERROR - Failed to execute job 261 for task dvc_push ([Errno 2] No such file or directory: 'GOOGLE_APPLICATION_CREDENTIALS=./opt/airflow/dags/src/gcs_creds.json'; 1247)
Traceback (most recent call last):
  File "/home/airflow/.local/lib/python3.12/site-packages/airflow/task/task_runner/standard_task_runner.py", line 117, in _start_by_fork
    ret = args.func(args, dag=self.dag)
          ^^^^^^^^^^^^^^^^^^^^^^^^^^^^^
  File "/home/airflow/.local/lib/python3.12/site-packages/airflow/cli/cli_config.py", line 49, in command
    return func(*args, **kwargs)
           ^^^^^^^^^^^^^^^^^^^^^
  File "/home/airflow/.local/lib/python3.12/site-packages/airflow/utils/cli.py", line 116, in wrapper
    return f(*args, **kwargs)
           ^^^^^^^^^^^^^^^^^^
  File "/home/airflow/.local/lib/python3.12/site-packages/airflow/cli/commands/task_command.py", line 483, in task_run
    task_return_code = _run_task_by_selected_method(args, _dag, ti)
                       ^^^^^^^^^^^^^^^^^^^^^^^^^^^^^^^^^^^^^^^^^^^^
  File "/home/airflow/.local/lib/python3.12/site-packages/airflow/cli/commands/task_command.py", line 256, in _run_task_by_selected_method
    return _run_raw_task(args, ti)
           ^^^^^^^^^^^^^^^^^^^^^^^
  File "/home/airflow/.local/lib/python3.12/site-packages/airflow/cli/commands/task_command.py", line 341, in _run_raw_task
    return ti._run_raw_task(
           ^^^^^^^^^^^^^^^^^
  File "/home/airflow/.local/lib/python3.12/site-packages/airflow/utils/session.py", line 97, in wrapper
    return func(*args, session=session, **kwargs)
           ^^^^^^^^^^^^^^^^^^^^^^^^^^^^^^^^^^^^^^
  File "/home/airflow/.local/lib/python3.12/site-packages/airflow/models/taskinstance.py", line 3006, in _run_raw_task
    return _run_raw_task(
           ^^^^^^^^^^^^^^
  File "/home/airflow/.local/lib/python3.12/site-packages/airflow/models/taskinstance.py", line 274, in _run_raw_task
    TaskInstance._execute_task_with_callbacks(
  File "/home/airflow/.local/lib/python3.12/site-packages/airflow/models/taskinstance.py", line 3161, in _execute_task_with_callbacks
    result = self._execute_task(context, task_orig)
             ^^^^^^^^^^^^^^^^^^^^^^^^^^^^^^^^^^^^^^
  File "/home/airflow/.local/lib/python3.12/site-packages/airflow/models/taskinstance.py", line 3185, in _execute_task
    return _execute_task(self, context, task_orig)
           ^^^^^^^^^^^^^^^^^^^^^^^^^^^^^^^^^^^^^^^
  File "/home/airflow/.local/lib/python3.12/site-packages/airflow/models/taskinstance.py", line 768, in _execute_task
    result = _execute_callable(context=context, **execute_callable_kwargs)
             ^^^^^^^^^^^^^^^^^^^^^^^^^^^^^^^^^^^^^^^^^^^^^^^^^^^^^^^^^^^^^
  File "/home/airflow/.local/lib/python3.12/site-packages/airflow/models/taskinstance.py", line 734, in _execute_callable
    return ExecutionCallableRunner(
           ^^^^^^^^^^^^^^^^^^^^^^^^
  File "/home/airflow/.local/lib/python3.12/site-packages/airflow/utils/operator_helpers.py", line 252, in run
    return self.func(*args, **kwargs)
           ^^^^^^^^^^^^^^^^^^^^^^^^^^
  File "/home/airflow/.local/lib/python3.12/site-packages/airflow/models/baseoperator.py", line 424, in wrapper
    return func(self, *args, **kwargs)
           ^^^^^^^^^^^^^^^^^^^^^^^^^^^
  File "/home/airflow/.local/lib/python3.12/site-packages/airflow/operators/python.py", line 238, in execute
    return_value = self.execute_callable()
                   ^^^^^^^^^^^^^^^^^^^^^^^
  File "/home/airflow/.local/lib/python3.12/site-packages/airflow/operators/python.py", line 256, in execute_callable
    return runner.run(*self.op_args, **self.op_kwargs)
           ^^^^^^^^^^^^^^^^^^^^^^^^^^^^^^^^^^^^^^^^^^^
  File "/home/airflow/.local/lib/python3.12/site-packages/airflow/utils/operator_helpers.py", line 252, in run
    return self.func(*args, **kwargs)
           ^^^^^^^^^^^^^^^^^^^^^^^^^^
  File "/opt/airflow/dags/dag.py", line 48, in dvc_push_to_gcs
    subprocess.run(
  File "/usr/local/lib/python3.12/subprocess.py", line 550, in run
    with Popen(*popenargs, **kwargs) as process:
         ^^^^^^^^^^^^^^^^^^^^^^^^^^^
  File "/usr/local/lib/python3.12/subprocess.py", line 1028, in __init__
    self._execute_child(args, executable, preexec_fn, close_fds,
  File "/usr/local/lib/python3.12/subprocess.py", line 1963, in _execute_child
    raise child_exception_type(errno_num, err_msg, err_filename)
FileNotFoundError: [Errno 2] No such file or directory: 'GOOGLE_APPLICATION_CREDENTIALS=./opt/airflow/dags/src/gcs_creds.json'
[2025-03-03T00:58:02.343+0000] {local_task_job_runner.py:266} INFO - Task exited with return code 1
[2025-03-03T00:58:02.362+0000] {taskinstance.py:3901} INFO - 0 downstream tasks scheduled from follow-on schedule check
[2025-03-03T00:58:02.363+0000] {local_task_job_runner.py:245} INFO - ::endgroup::
