[2025-03-02T08:12:02.947+0000] {local_task_job_runner.py:123} INFO - ::group::Pre task execution logs
[2025-03-02T08:12:02.955+0000] {taskinstance.py:2614} INFO - Dependencies all met for dep_context=non-requeueable deps ti=<TaskInstance: scraping_pipeline_gcs.validate_data manual__2025-03-02T08:11:47.723536+00:00 [queued]>
[2025-03-02T08:12:02.959+0000] {taskinstance.py:2614} INFO - Dependencies all met for dep_context=requeueable deps ti=<TaskInstance: scraping_pipeline_gcs.validate_data manual__2025-03-02T08:11:47.723536+00:00 [queued]>
[2025-03-02T08:12:02.959+0000] {taskinstance.py:2867} INFO - Starting attempt 1 of 3
[2025-03-02T08:12:02.963+0000] {taskinstance.py:2890} INFO - Executing <Task(PythonOperator): validate_data> on 2025-03-02 08:11:47.723536+00:00
[2025-03-02T08:12:02.969+0000] {warnings.py:112} WARNING - /home/***/.local/lib/python3.12/site-packages/***/task/task_runner/standard_task_runner.py:70: DeprecationWarning: This process (pid=1589) is multi-threaded, use of fork() may lead to deadlocks in the child.
  pid = os.fork()

[2025-03-02T08:12:02.970+0000] {standard_task_runner.py:72} INFO - Started process 1591 to run task
[2025-03-02T08:12:02.971+0000] {standard_task_runner.py:104} INFO - Running: ['***', 'tasks', 'run', 'scraping_pipeline_gcs', 'validate_data', 'manual__2025-03-02T08:11:47.723536+00:00', '--job-id', '49', '--raw', '--subdir', 'DAGS_FOLDER/dag.py', '--cfg-path', '/tmp/tmpvu9u0p1u']
[2025-03-02T08:12:02.972+0000] {standard_task_runner.py:105} INFO - Job 49: Subtask validate_data
[2025-03-02T08:12:02.997+0000] {task_command.py:467} INFO - Running <TaskInstance: scraping_pipeline_gcs.validate_data manual__2025-03-02T08:11:47.723536+00:00 [running]> on host 8b8ee4ab00d2
[2025-03-02T08:12:03.300+0000] {taskinstance.py:3134} INFO - Exporting env vars: AIRFLOW_CTX_DAG_OWNER='***' AIRFLOW_CTX_DAG_ID='scraping_pipeline_gcs' AIRFLOW_CTX_TASK_ID='validate_data' AIRFLOW_CTX_EXECUTION_DATE='2025-03-02T08:11:47.723536+00:00' AIRFLOW_CTX_TRY_NUMBER='1' AIRFLOW_CTX_DAG_RUN_ID='manual__2025-03-02T08:11:47.723536+00:00'
[2025-03-02T08:12:03.301+0000] {logging_mixin.py:190} INFO - Task instance is in running state
[2025-03-02T08:12:03.301+0000] {logging_mixin.py:190} INFO -  Previous state of the Task instance: queued
[2025-03-02T08:12:03.301+0000] {logging_mixin.py:190} INFO - Current task name:validate_data state:running start_date:2025-03-02 08:12:02.955808+00:00
[2025-03-02T08:12:03.302+0000] {logging_mixin.py:190} INFO - Dag name:scraping_pipeline_gcs and current dag run status:running
[2025-03-02T08:12:03.302+0000] {taskinstance.py:732} INFO - ::endgroup::
[2025-03-02T08:12:03.303+0000] {taskinstance.py:3313} ERROR - Task failed with exception
Traceback (most recent call last):
  File "/home/airflow/.local/lib/python3.12/site-packages/airflow/models/taskinstance.py", line 768, in _execute_task
    result = _execute_callable(context=context, **execute_callable_kwargs)
             ^^^^^^^^^^^^^^^^^^^^^^^^^^^^^^^^^^^^^^^^^^^^^^^^^^^^^^^^^^^^^
  File "/home/airflow/.local/lib/python3.12/site-packages/airflow/models/taskinstance.py", line 734, in _execute_callable
    return ExecutionCallableRunner(
           ^^^^^^^^^^^^^^^^^^^^^^^^
  File "/home/airflow/.local/lib/python3.12/site-packages/airflow/utils/operator_helpers.py", line 252, in run
    return self.func(*args, **kwargs)
           ^^^^^^^^^^^^^^^^^^^^^^^^^^
  File "/home/airflow/.local/lib/python3.12/site-packages/airflow/models/baseoperator.py", line 424, in wrapper
    return func(self, *args, **kwargs)
           ^^^^^^^^^^^^^^^^^^^^^^^^^^^
  File "/home/airflow/.local/lib/python3.12/site-packages/airflow/operators/python.py", line 238, in execute
    return_value = self.execute_callable()
                   ^^^^^^^^^^^^^^^^^^^^^^^
  File "/home/airflow/.local/lib/python3.12/site-packages/airflow/operators/python.py", line 256, in execute_callable
    return runner.run(*self.op_args, **self.op_kwargs)
           ^^^^^^^^^^^^^^^^^^^^^^^^^^^^^^^^^^^^^^^^^^^
  File "/home/airflow/.local/lib/python3.12/site-packages/airflow/utils/operator_helpers.py", line 252, in run
    return self.func(*args, **kwargs)
           ^^^^^^^^^^^^^^^^^^^^^^^^^^
  File "/opt/airflow/dags/dag.py", line 37, in validate_scraped_text
    raise AirflowFailException("No .txt files found after scraping!")
airflow.exceptions.AirflowFailException: No .txt files found after scraping!
[2025-03-02T08:12:03.311+0000] {logging_mixin.py:190} INFO - Task instance in failure state
[2025-03-02T08:12:03.311+0000] {logging_mixin.py:190} INFO - Task start:2025-03-02 08:12:02.955808+00:00 end:2025-03-02 08:12:03.311217+00:00 duration:0.355409
[2025-03-02T08:12:03.311+0000] {logging_mixin.py:190} INFO - Task:<Task(PythonOperator): validate_data> dag:<DAG: scraping_pipeline_gcs> dagrun:<DagRun scraping_pipeline_gcs @ 2025-03-02 08:11:47.723536+00:00: manual__2025-03-02T08:11:47.723536+00:00, state:running, queued_at: 2025-03-02 08:11:47.741757+00:00. externally triggered: True>
[2025-03-02T08:12:03.311+0000] {logging_mixin.py:190} INFO - Failure caused by No .txt files found after scraping!
[2025-03-02T08:12:03.311+0000] {taskinstance.py:1226} INFO - Immediate failure requested. Marking task as FAILED. dag_id=scraping_pipeline_gcs, task_id=validate_data, run_id=manual__2025-03-02T08:11:47.723536+00:00, execution_date=20250302T081147, start_date=20250302T081202, end_date=20250302T081203
[2025-03-02T08:12:03.324+0000] {taskinstance.py:341} INFO - ::group::Post task execution logs
[2025-03-02T08:12:03.324+0000] {standard_task_runner.py:124} ERROR - Failed to execute job 49 for task validate_data (No .txt files found after scraping!; 1591)
Traceback (most recent call last):
  File "/home/airflow/.local/lib/python3.12/site-packages/airflow/task/task_runner/standard_task_runner.py", line 117, in _start_by_fork
    ret = args.func(args, dag=self.dag)
          ^^^^^^^^^^^^^^^^^^^^^^^^^^^^^
  File "/home/airflow/.local/lib/python3.12/site-packages/airflow/cli/cli_config.py", line 49, in command
    return func(*args, **kwargs)
           ^^^^^^^^^^^^^^^^^^^^^
  File "/home/airflow/.local/lib/python3.12/site-packages/airflow/utils/cli.py", line 116, in wrapper
    return f(*args, **kwargs)
           ^^^^^^^^^^^^^^^^^^
  File "/home/airflow/.local/lib/python3.12/site-packages/airflow/cli/commands/task_command.py", line 483, in task_run
    task_return_code = _run_task_by_selected_method(args, _dag, ti)
                       ^^^^^^^^^^^^^^^^^^^^^^^^^^^^^^^^^^^^^^^^^^^^
  File "/home/airflow/.local/lib/python3.12/site-packages/airflow/cli/commands/task_command.py", line 256, in _run_task_by_selected_method
    return _run_raw_task(args, ti)
           ^^^^^^^^^^^^^^^^^^^^^^^
  File "/home/airflow/.local/lib/python3.12/site-packages/airflow/cli/commands/task_command.py", line 341, in _run_raw_task
    return ti._run_raw_task(
           ^^^^^^^^^^^^^^^^^
  File "/home/airflow/.local/lib/python3.12/site-packages/airflow/utils/session.py", line 97, in wrapper
    return func(*args, session=session, **kwargs)
           ^^^^^^^^^^^^^^^^^^^^^^^^^^^^^^^^^^^^^^
  File "/home/airflow/.local/lib/python3.12/site-packages/airflow/models/taskinstance.py", line 3006, in _run_raw_task
    return _run_raw_task(
           ^^^^^^^^^^^^^^
  File "/home/airflow/.local/lib/python3.12/site-packages/airflow/models/taskinstance.py", line 274, in _run_raw_task
    TaskInstance._execute_task_with_callbacks(
  File "/home/airflow/.local/lib/python3.12/site-packages/airflow/models/taskinstance.py", line 3161, in _execute_task_with_callbacks
    result = self._execute_task(context, task_orig)
             ^^^^^^^^^^^^^^^^^^^^^^^^^^^^^^^^^^^^^^
  File "/home/airflow/.local/lib/python3.12/site-packages/airflow/models/taskinstance.py", line 3185, in _execute_task
    return _execute_task(self, context, task_orig)
           ^^^^^^^^^^^^^^^^^^^^^^^^^^^^^^^^^^^^^^^
  File "/home/airflow/.local/lib/python3.12/site-packages/airflow/models/taskinstance.py", line 768, in _execute_task
    result = _execute_callable(context=context, **execute_callable_kwargs)
             ^^^^^^^^^^^^^^^^^^^^^^^^^^^^^^^^^^^^^^^^^^^^^^^^^^^^^^^^^^^^^
  File "/home/airflow/.local/lib/python3.12/site-packages/airflow/models/taskinstance.py", line 734, in _execute_callable
    return ExecutionCallableRunner(
           ^^^^^^^^^^^^^^^^^^^^^^^^
  File "/home/airflow/.local/lib/python3.12/site-packages/airflow/utils/operator_helpers.py", line 252, in run
    return self.func(*args, **kwargs)
           ^^^^^^^^^^^^^^^^^^^^^^^^^^
  File "/home/airflow/.local/lib/python3.12/site-packages/airflow/models/baseoperator.py", line 424, in wrapper
    return func(self, *args, **kwargs)
           ^^^^^^^^^^^^^^^^^^^^^^^^^^^
  File "/home/airflow/.local/lib/python3.12/site-packages/airflow/operators/python.py", line 238, in execute
    return_value = self.execute_callable()
                   ^^^^^^^^^^^^^^^^^^^^^^^
  File "/home/airflow/.local/lib/python3.12/site-packages/airflow/operators/python.py", line 256, in execute_callable
    return runner.run(*self.op_args, **self.op_kwargs)
           ^^^^^^^^^^^^^^^^^^^^^^^^^^^^^^^^^^^^^^^^^^^
  File "/home/airflow/.local/lib/python3.12/site-packages/airflow/utils/operator_helpers.py", line 252, in run
    return self.func(*args, **kwargs)
           ^^^^^^^^^^^^^^^^^^^^^^^^^^
  File "/opt/airflow/dags/dag.py", line 37, in validate_scraped_text
    raise AirflowFailException("No .txt files found after scraping!")
airflow.exceptions.AirflowFailException: No .txt files found after scraping!
[2025-03-02T08:12:03.373+0000] {local_task_job_runner.py:266} INFO - Task exited with return code 1
[2025-03-02T08:12:03.392+0000] {taskinstance.py:3901} INFO - 0 downstream tasks scheduled from follow-on schedule check
[2025-03-02T08:12:03.395+0000] {local_task_job_runner.py:245} INFO - ::endgroup::
